Workbook

Sheet horno
B1: HORNO PEQ
A2: 8H | B2: =400*8 -> 3200
A3: 10.5H | B3: =450*10.5 -> 4725
B5: HORNO GRAN
A6: 8H | B6: =420*8 -> 3360
A7: 10.5H | B7: =550*10.5 -> 5775
B13: =+B2 -> 3200
B15: =+B2+B6 -> 6560

Sheet ANALISIS PROD
A1: Item ID | B1: Item Description | C1: ene | D1: feb | E1: mar | F1: abr | G1: may | H1: jun | I1: jul | J1: ago | K1: sep | L1: oct | M1: nov | N1: dic | O1: 45292 | P1: 45346 | Q1: 45375 | R1: 45406 | S1: TOTAL PACAS | U1: PACAS PROMEDIO MENSUAL | V1: (+) % INCREMENTO | W1: STOCK ACTUAL BODEGA | X1: STOK SEMANAL PACAS PROMEDIO | Y1: DIF PACAS | Z1: DIF UNIDADES | AB1: PACAS PRODUCCION DIARIA | AC1: UNIDAD MANEJO | AD1: UNIDADES MENSUALES | AE1: UNIDADES DIARIAS | AF1: KG | AG1: KILOS DIARIOS | AI1: KILOS A CUMPLIR
A2: PT10001 | B2: PIPAS E SAL - PACAS 400 U T-10 | C2: 1016.5 | D2: 658.5 | E2: 756 | F2: 679.5 | G2: 895.5 | H2: 789 | I2: 735 | J2: 905 | K2: 745 | L2: 791.5 | M2: 664.5 | N2: 551.5 | O2: 549.5 | P2: 616.5 | Q2: 714 | R2: 645 | S2: =SUM(C2:R2) -> 11712.5 | U2: =+AVERAGE(C2:R2) -> 732.03125 | V2: =+U2*$V$47+U2 -> 785.10352 | W2: =+VLOOKUP(A2,'INVENTARIO ACTUAL'!$A$2:$E$40,5,FALSE) -> 235.5 | X2: =+V2/4 -> 196.27588 | Y2: =+W2-X2 -> 39.224121 | Z2: =+Y2*AC2 -> 15689.648 | AB2: =+V2/20 -> 39.255176 | AC2: 400 | AD2: =+V2*AC2 -> 314041.41 | AE2: =+AD2/20 -> 15702.07 | AF2: 0.019 | AG2: =+AE2*AF2 -> 298.33934 | AI2: =+IF(Z2<=0,Z2*AF2,0) -> 0
A3: PT10002 | B3: PIPAS E SAL - PACAS 400 U T-20 | C3: 699.5 | D3: 522 | E3: 643 | F3: 588 | G3: 591 | H3: 536 | I3: 563 | J3: 617 | K3: 565 | L3: 530 | M3: 507 | N3: 411.5 | O3: 562.5 | P3: 511 | Q3: 553.5 | R3: 474.5 | S3: =SUM(C3:R3) -> 8874.5 | U3: =+AVERAGE(C3:R3) -> 554.65625 | V3: =+U3*$V$47+U3 -> 594.86883 | W3: =+VLOOKUP(A3,'INVENTARIO ACTUAL'!$A$2:$E$40,5,FALSE) -> 223.5 | X3: =+V3/4 -> 148.71721 | Y3: =+W3-X3 -> 74.782793 | Z3: =+Y3*AC3 -> 29913.117 | AB3: =+V3/20 -> 29.743441 | AC3: 400 | AD3: =+V3*AC3 -> 237947.53 | AE3: =+AD3/20 -> 11897.377 | AF3: 0.019 | AG3: =+AE3*AF3 -> 226.05015 | AI3: =+IF(Z3<=0,Z3*AF3,0) -> 0
A4: PT11001 | B4: PIPAS E PIC - PACAS 400 U T-10 | C4: 63.5 | D4: 36 | E4: 79 | F4: 85 | G4: 93 | H4: 54 | I4: 62 | J4: 73 | K4: 53 | L4: 53 | M4: 32 | N4: 27 | O4: 35 | P4: 34 | Q4: 33 | R4: 43 | S4: =SUM(C4:R4) -> 855.5 | U4: =+AVERAGE(C4:R4) -> 53.46875 | V4: =+U4*$V$47+U4 -> 57.345234 | W4: =+VLOOKUP(A4,'INVENTARIO ACTUAL'!$A$2:$E$40,5,FALSE) -> 71 | X4: =+V4/4 -> 14.336309 | Y4: =+W4-X4 -> 56.663691 | Z4: =+Y4*AC4 -> 22665.477 | AB4: =+V4/20 -> 2.8672617 | AC4: 400 | AD4: =+V4*AC4 -> 22938.094 | AE4: =+AD4/20 -> 1146.9047 | AF4: 0.019 | AG4: =+AE4*AF4 -> 21.791189 | AI4: =+IF(Z4<=0,Z4*AF4,0) -> 0
A5: PT11002 | B5: PIPAS E PIC - PACAS 400 U T-20 | C5: 17 | D5: 9 | E5: 15 | F5: 5 | G5: 8 | H5: 8 | I5: 15 | J5: 18 | K5: 8 | L5: 8 | M5: 7 | N5: 11 | O5: 9 | P5: 12 | Q5: 4 | R5: 8 | S5: =SUM(C5:R5) -> 162 | U5: =+AVERAGE(C5:R5) -> 10.125 | V5: =+U5*$V$47+U5 -> 10.859063 | W5: =+VLOOKUP(A5,'INVENTARIO ACTUAL'!$A$2:$E$40,5,FALSE) -> 10 | X5: =+V5/4 -> 2.7147656 | Y5: =+W5-X5 -> 7.2852344 | Z5: =+Y5*AC5 -> 2914.0938 | AB5: =+V5/20 -> 0.54295313 | AC5: 400 | AD5: =+V5*AC5 -> 4343.625 | AE5: =+AD5/20 -> 217.18125 | AF5: 0.019 | AG5: =+AE5*AF5 -> 4.1264437 | AI5: =+IF(Z5<=0,Z5*AF5,0) -> 0
A6: PT12001 | B6: PIPAS E LIM - PACAS 400 U T-10 | C6: 533 | D6: 481 | E6: 544 | F6: 418.5 | G6: 606 | H6: 496 | I6: 562.5 | J6: 559 | K6: 514 | L6: 496 | M6: 421 | N6: 297 | O6: 411 | P6: 358 | Q6: 445 | R6: 357 | S6: =SUM(C6:R6) -> 7499 | U6: =+AVERAGE(C6:R6) -> 468.6875 | V6: =+U6*$V$47+U6 -> 502.66734 | W6: =+VLOOKUP(A6,'INVENTARIO ACTUAL'!$A$2:$E$40,5,FALSE) -> 179 | X6: =+V6/4 -> 125.66684 | Y6: =+W6-X6 -> 53.333164 | Z6: =+Y6*AC6 -> 21333.266 | AB6: =+V6/20 -> 25.133367 | AC6: 400 | AD6: =+V6*AC6 -> 201066.94 | AE6: =+AD6/20 -> 10053.347 | AF6: 0.019 | AG6: =+AE6*AF6 -> 191.01359 | AI6: =+IF(Z6<=0,Z6*AF6,0) -> 0
A7: PT12002 | B7: PIPAS E LIM - PACAS 400 U T-20 | C7: 150 | D7: 81 | E7: 76 | F7: 91 | G7: 102 | H7: 77 | I7: 121 | J7: 94 | K7: 99 | L7: 93 | M7: 47 | N7: 78 | O7: 77 | P7: 66 | Q7: 66 | R7: 83 | S7: =SUM(C7:R7) -> 1401 | U7: =+AVERAGE(C7:R7) -> 87.5625 | V7: =+U7*$V$47+U7 -> 93.910781 | W7: =+VLOOKUP(A7,'INVENTARIO ACTUAL'!$A$2:$E$40,5,FALSE) -> 67 | X7: =+V7/4 -> 23.477695 | Y7: =+W7-X7 -> 43.522305 | Z7: =+Y7*AC7 -> 17408.922 | AB7: =+V7/20 -> 4.6955391 | AC7: 400 | AD7: =+V7*AC7 -> 37564.312 | AE7: =+AD7/20 -> 1878.2156 | AF7: 0.019 | AG7: =+AE7*AF7 -> 35.686097 | AI7: =+IF(Z7<=0,Z7*AF7,0) -> 0
A8: PT13001 | B8: PIPAS E MAR - PACAS 400 U T-10 | C8: 155 | D8: 128 | E8: 80 | F8: 133 | G8: 224 | H8: 141 | I8: 160 | J8: 157 | K8: 160 | L8: 153 | M8: 83 | N8: 76 | O8: 103 | P8: 99 | Q8: 82 | R8: 85 | S8: =SUM(C8:R8) -> 2019 | U8: =+AVERAGE(C8:R8) -> 126.1875 | V8: =+U8*$V$47+U8 -> 135.33609 | W8: =+VLOOKUP(A8,'INVENTARIO ACTUAL'!$A$2:$E$40,5,FALSE) -> 83 | X8: =+V8/4 -> 33.834023 | Y8: =+W8-X8 -> 49.165977 | Z8: =+Y8*AC8 -> 19666.391 | AB8: =+V8/20 -> 6.7668047 | AC8: 400 | AD8: =+V8*AC8 -> 54134.438 | AE8: =+AD8/20 -> 2706.7219 | AF8: 0.019 | AG8: =+AE8*AF8 -> 51.427716 | AI8: =+IF(Z8<=0,Z8*AF8,0) -> 0
A9: PT13002 | B9: PIPAS E MAR - PACAS 400 U T-20 | C9: 0 | D9: 0 | E9: 0 | F9: 0 | G9: 0 | H9: 0 | I9: 0 | J9: 0 | K9: 0 | L9: 0 | M9: 0 | N9: 0 | O9: 0 | S9: =SUM(C9:R9) -> 0 | U9: =+AVERAGE(C9:R9) -> 0 | V9: =+U9*$V$47+U9 -> 0 | X9: =+V9/4 -> 0 | Y9: =+W9-X9 -> 0 | Z9: =+Y9*AC9 -> 0 | AB9: =+V9/20 -> 0 | AC9: 400 | AD9: =+V9*AC9 -> 0 | AE9: =+AD9/20 -> 0 | AG9: =+AE9*AF9 -> 0 | AI9: =+IF(Z9<=0,Z9*AF9,0) -> 0
A10: PT20001 | B10: PIPAS MGA VER-PACAS 400 T-10 | C10: 1493.5 | D10: 965 | E10: 944.5 | F10: 1022 | G10: 1321 | H10: 1067 | I10: 1015.5 | J10: 1277 | K10: 1254 | L10: 1110.5 | M10: 1142 | N10: 953 | O10: 987 | P10: 1004.5 | Q10: 1137 | R10: 930.5 | S10: =SUM(C10:R10) -> 17624 | U10: =+AVERAGE(C10:R10) -> 1101.5 | V10: =+U10*$V$47+U10 -> 1181.3588 | W10: =+VLOOKUP(A10,'INVENTARIO ACTUAL'!$A$2:$E$40,5,FALSE) -> 497.5 | X10: =+V10/4 -> 295.33969 | Y10: =+W10-X10 -> 202.16031 | Z10: =+Y10*AC10 -> 80864.125 | AB10: =+V10/20 -> 59.067938 | AC10: 400 | AD10: =+V10*AC10 -> 472543.5 | AE10: =+AD10/20 -> 23627.175 | AF10: 0.019 | AG10: =+AE10*AF10 -> 448.91633 | AI10: =+IF(Z10<=0,Z10*AF10,0) -> 0
A11: PT20002 | B11: PIPAS MGA VER-PACAS 400 T-20 | C11: 3672 | D11: 3007 | E11: 3486 | F11: 3042.5 | G11: 3182.5 | H11: 2785 | I11: 2958.5 | J11: 2587 | K11: 3053 | L11: 2266.5 | M11: 2789.5 | N11: 2109.5 | O11: 2812.5 | P11: 2813.5 | Q11: 3044.5 | R11: 2173.5 | S11: =SUM(C11:R11) -> 45783 | U11: =+AVERAGE(C11:R11) -> 2861.4375 | V11: =+U11*$V$47+U11 -> 3068.8917 | W11: =+VLOOKUP(A11,'INVENTARIO ACTUAL'!$A$2:$E$40,5,FALSE) -> 1225 | X11: =+V11/4 -> 767.22293 | Y11: =+W11-X11 -> 457.77707 | Z11: =+Y11*AC11 -> 183110.83 | AB11: =+V11/20 -> 153.44459 | AC11: 400 | AD11: =+V11*AC11 -> 1227556.7 | AE11: =+AD11/20 -> 61377.834 | AF11: 0.019 | AG11: =+AE11*AF11 -> 1166.1789 | AI11: =+IF(Z11<=0,Z11*AF11,0) -> 0
A12: PT20013 | B12: PIPAS MGA VERDE P 400 T20+2 | C12: 0 | D12: 0 | E12: 0 | F12: 0 | G12: 0 | H12: 0 | I12: 0 | J12: 0 | K12: 0 | L12: 0 | M12: 50 | N12: 142 | O12: 227 | P12: 185 | Q12: 234 | R12: 307 | S12: =SUM(C12:R12) -> 1145 | U12: =+AVERAGE(C12:R12) -> 71.5625 | V12: =+U12*$V$47+U12 -> 76.750781 | W12: =+VLOOKUP(A12,'INVENTARIO ACTUAL'!$A$2:$E$40,5,FALSE) -> 62 | X12: =+V12/4 -> 19.187695 | Y12: =+W12-X12 -> 42.812305
A13: PT21001 | B13: PIPAS MGA ACID-LEM-PAC 400 T10 | C13: 1866 | D13: 1140.5 | E13: 1069 | F13: 1226.5 | G13: 1562.5 | H13: 1574 | I13: 1639 | J13: 1741.5 | K13: 2214 | L13: 1919 | M13: 1802.5 | N13: 1558 | O13: 1608 | P13: 1581.5 | Q13: 1667 | R13: 1565 | S13: =SUM(C13:R13) -> 25734 | U13: =+AVERAGE(C13:R13) -> 1608.375 | V13: =+U13*$V$47+U13 -> 1724.9822 | W13: =+VLOOKUP(A13,'INVENTARIO ACTUAL'!$A$2:$E$40,5,FALSE) -> 389 | X13: =+V13/4 -> 431.24555 | Y13: =+W13-X13 -> -42.245547 | Z13: =+Y13*AC13 -> -16898.219 | AB13: =+V13/20 -> 86.249109 | AC13: 400 | AD13: =+V13*AC13 -> 689992.88 | AE13: =+AD13/20 -> 34499.644 | AF13: 0.019 | AG13: =+AE13*AF13 -> 655.49323 | AI13: =+IF(Z13<=0,Z13*AF13,0) -> -321.06616
A14: PT21002 | B14: PIPAS MGA ACID-LEM-PAC 400 T20 | C14: 2262 | D14: 1771.5 | E14: 2323 | F14: 2068 | G14: 2157.5 | H14: 1886.5 | I14: 1744.5 | J14: 1671 | K14: 2083 | L14: 764.5 | M14: 1290 | N14: 1546 | O14: 2114.5 | P14: 2003.5 | Q14: 2435.5 | R14: 1887 | S14: =SUM(C14:R14) -> 30008 | U14: =+AVERAGE(C14:R14) -> 1875.5 | V14: =+U14*$V$47+U14 -> 2011.4738 | W14: =+VLOOKUP(A14,'INVENTARIO ACTUAL'!$A$2:$E$40,5,FALSE) -> 650.5 | X14: =+V14/4 -> 502.86844 | Y14: =+W14-X14 -> 147.63156 | Z14: =+Y14*AC14 -> 59052.625 | AB14: =+V14/20 -> 100.57369 | AC14: 400 | AD14: =+V14*AC14 -> 804589.5 | AE14: =+AD14/20 -> 40229.475 | AF14: 0.019 | AG14: =+AE14*AF14 -> 764.36002 | AI14: =+IF(Z14<=0,Z14*AF14,0) -> 0
A15: PT21006 | B15: PIPAS MGA ACID-LEM P 400 T20+2 | C15: 0 | D15: 0 | E15: 0 | F15: 0 | G15: 0 | H15: 0 | I15: 0 | J15: 0 | K15: 0 | L15: 1214 | M15: 917 | N15: 136 | O15: 257 | P15: 242 | Q15: 241 | R15: 350 | S15: =SUM(C15:R15) -> 3357 | U15: =+AVERAGE(C15:R15) -> 209.8125 | V15: =+U15*$V$47+U15 -> 225.02391 | W15: =+VLOOKUP(A15,'INVENTARIO ACTUAL'!$A$2:$E$40,5,FALSE) -> 57 | X15: =+V15/4 -> 56.255977 | Y15: =+W15-X15 -> 0.74402344 | Z15: =+Y15*AC15 -> 327.37031 | AB15: =+V15/20 -> 11.251195 | AC15: 440 | AD15: =+V15*AC15 -> 99010.519 | AE15: =+AD15/20 -> 4950.5259 | AG15: =+AE15*AF15 -> 0 | AI15: =+IF(Z15<=0,Z15*AF15,0) -> 0
A16: PT20006 | B16: PIPAS MGA VER PACA 400 U GRN | C16: 13 | D16: 9 | E16: 9 | F16: 6 | G16: 6 | H16: 8 | I16: 19 | J16: 19 | K16: 16 | L16: 17 | M16: 10 | N16: 14 | O16: 14 | P16: 5 | Q16: 6 | R16: 8 | S16: =SUM(C16:R16) -> 179 | U16: =+AVERAGE(C16:R16) -> 11.1875 | V16: =+U16*$V$47+U16 -> 11.998594 | W16: =+VLOOKUP(A16,'INVENTARIO ACTUAL'!$A$2:$E$40,5,FALSE) -> 11 | X16: =+V16/4 -> 2.9996484 | Y16: =+W16-X16 -> 8.0003516 | Z16: =+Y16*AC16 -> 3200.1406 | AB16: =+V16/20 -> 0.59992969 | AC16: 400 | AD16: =+V16*AC16 -> 4799.4375 | AE16: =+AD16/20 -> 239.97188 | AF16: 0.019 | AG16: =+AE16*AF16 -> 4.5594656 | AI16: =+IF(Z16<=0,Z16*AF16,0) -> 0
A17: PT21005 | B17: PIPAS MGA ACID-LEM PACA 400 GR | C17: 12 | D17: 5 | E17: 9 | F17: 4 | G17: 7 | H17: 6 | I17: 4 | J17: 9 | K17: 3 | L17: 0 | M17: 0 | N17: 0 | O17: 0 | S17: =SUM(C17:R17) -> 59 | U17: =+AVERAGE(C17:R17) -> 4.5384615 | V17: =+U17*$V$47+U17 -> 4.8675 | W17: =+VLOOKUP(A17,'INVENTARIO ACTUAL'!$A$2:$E$40,5,FALSE) -> 3 | X17: =+V17/4 -> 1.216875 | Y17: =+W17-X17 -> 1.783125 | Z17: =+Y17*AC17 -> 713.25 | AB17: =+V17/20 -> 0.243375 | AC17: 400 | AD17: =+V17*AC17 -> 1947 | AE17: =+AD17/20 -> 97.35 | AF17: 0.019 | AG17: =+AE17*AF17 -> 1.84965 | AI17: =+IF(Z17<=0,Z17*AF17,0) -> 0
A18: PT22001 | B18: PIPAS MGA MRAC-LIM-PAC 400 T10 | C18: 1289.5 | D18: 795 | E18: 909.5 | F18: 721 | G18: 1150 | H18: 1025.5 | I18: 1102 | J18: 1077.5 | K18: 1123.5 | L18: 1081 | M18: 888 | N18: 679.5 | O18: 827 | P18: 751 | Q18: 793 | R18: 761 | S18: =SUM(C18:R18) -> 14974 | U18: =+AVERAGE(C18:R18) -> 935.875 | V18: =+U18*$V$47+U18 -> 1003.7259 | W18: =+VLOOKUP(A18,'INVENTARIO ACTUAL'!$A$2:$E$40,5,FALSE) -> 187.5 | X18: =+V18/4 -> 250.93148 | Y18: =+W18-X18 -> -63.431484 | Z18: =+Y18*AC18 -> -25372.594 | AB18: =+V18/20 -> 50.186297 | AC18: 400 | AD18: =+V18*AC18 -> 401490.38 | AE18: =+AD18/20 -> 20074.519 | AF18: 0.019 | AG18: =+AE18*AF18 -> 381.41586 | AI18: =+IF(Z18<=0,Z18*AF18,0) -> -482.07928
A19: PT22002 | B19: PIPAS MGA MRAC-LIM-PAC 400 T20 | C19: 930 | D19: 697 | E19: 683 | F19: 677 | G19: 732.5 | H19: 649.5 | I19: 642.5 | J19: 646 | K19: 645.5 | L19: 606 | M19: 643 | N19: 521 | O19: 645.5 | P19: 594 | Q19: 707 | R19: 598.5 | S19: =SUM(C19:R19) -> 10618 | U19: =+AVERAGE(C19:R19) -> 663.625 | V19: =+U19*$V$47+U19 -> 711.73781 | W19: =+VLOOKUP(A19,'INVENTARIO ACTUAL'!$A$2:$E$40,5,FALSE) -> 250 | X19: =+V19/4 -> 177.93445 | Y19: =+W19-X19 -> 72.065547 | Z19: =+Y19*AC19 -> 28826.219 | AB19: =+V19/20 -> 35.586891 | AC19: 400 | AD19: =+V19*AC19 -> 284695.12 | AE19: =+AD19/20 -> 14234.756 | AF19: 0.019 | AG19: =+AE19*AF19 -> 270.46037 | AI19: =+IF(Z19<=0,Z19*AF19,0) -> 0
A20: PT23001 | B20: PIPAS MGA PIC-LIM-PAC 400 T-10 | C20: 547 | D20: 425.5 | E20: 363 | F20: 390 | G20: 587.5 | H20: 537.5 | I20: 644.5 | J20: 734.5 | K20: 618 | L20: 695.5 | M20: 496 | N20: 491 | O20: 460.5 | P20: 429.5 | Q20: 565 | R20: 488.5 | S20: =SUM(C20:R20) -> 8473.5 | U20: =+AVERAGE(C20:R20) -> 529.59375 | V20: =+U20*$V$47+U20 -> 567.9893 | W20: =+VLOOKUP(A20,'INVENTARIO ACTUAL'!$A$2:$E$40,5,FALSE) -> 137 | X20: =+V20/4 -> 141.99732 | Y20: =+W20-X20 -> -4.9973242 | Z20: =+Y20*AC20 -> -1998.9297 | AB20: =+V20/20 -> 28.399465 | AC20: 400 | AD20: =+V20*AC20 -> 227195.72 | AE20: =+AD20/20 -> 11359.786 | AF20: 0.019 | AG20: =+AE20*AF20 -> 215.83593 | AI20: =+IF(Z20<=0,Z20*AF20,0) -> -37.979664
A21: PT23002 | B21: PIPAS MGA PIC-LIM-PAC 400 T-20 | C21: 541.5 | D21: 469 | E21: 518 | F21: 521.5 | G21: 541 | H21: 533 | I21: 435.5 | J21: 442 | K21: 466.5 | L21: 475 | M21: 470 | N21: 399 | O21: 536.5 | P21: 476 | Q21: 593 | R21: 506 | S21: =SUM(C21:R21) -> 7923.5 | U21: =+AVERAGE(C21:R21) -> 495.21875 | V21: =+U21*$V$47+U21 -> 531.12211 | W21: =+VLOOKUP(A21,'INVENTARIO ACTUAL'!$A$2:$E$40,5,FALSE) -> 162.5 | X21: =+V21/4 -> 132.78053 | Y21: =+W21-X21 -> 29.719473 | Z21: =+Y21*AC21 -> 11887.789 | AB21: =+V21/20 -> 26.556105 | AC21: 400 | AD21: =+V21*AC21 -> 212448.84 | AE21: =+AD21/20 -> 10622.442 | AF21: 0.019 | AG21: =+AE21*AF21 -> 201.8264 | AI21: =+IF(Z21<=0,Z21*AF21,0) -> 0
S22: =SUM(C22:R22) -> 0 | U22: 0 | AE22: =+AD22/20 -> 0 | AG22: =+AE22*AF22 -> 0 | AI22: =+IF(Z22<=0,Z22*AF22,0) -> 0
A23: PT10003 | B23: PIPAS E SAL 36 U GRN 120G | C23: 475 | D23: 403 | E23: 516 | F23: 489 | G23: 418 | H23: 434 | I23: 493 | J23: 547 | K23: 502 | L23: 455 | M23: 505 | N23: 343 | O23: 572 | P23: 426 | Q23: 533 | R23: 511 | S23: =SUM(C23:R23) -> 7622 | U23: =+AVERAGE(C23:R23) -> 476.375 | V23: =+U23*$V$47+U23 -> 510.91219 | W23: =+VLOOKUP(A23,'INVENTARIO ACTUAL'!$A$2:$E$40,5,FALSE) -> 135 | X23: =+V23/4 -> 127.72805 | Y23: =+W23-X23 -> 7.2719531 | Z23: =+Y23*AC23 -> 261.79031 | AB23: =+V23/20 -> 25.545609 | AC23: 36 | AD23: =+V23*AC23 -> 18392.839 | AE23: =+AD23/20 -> 919.64194 | AF23: 0.12 | AG23: =+AE23*AF23 -> 110.35703 | AI23: =+IF(Z23<=0,Z23*AF23,0) -> 0
A24: PT10004 | B24: C PIPAS E SAL 36 U GRN 120G | C24: 877 | D24: 666 | E24: 808 | F24: 799 | G24: 996 | H24: 743 | I24: 964 | J24: 754 | K24: 860 | L24: 1214 | M24: 995 | N24: 583 | O24: 818 | P24: 1001 | Q24: 1234 | R24: 741 | S24: =SUM(C24:R24) -> 14053 | U24: =+AVERAGE(C24:R24) -> 878.3125 | V24: =+U24*$V$47+U24 -> 941.99016 | W24: =+VLOOKUP(A24,'INVENTARIO ACTUAL'!$A$2:$E$40,5,FALSE) -> 157 | X24: =+V24/4 -> 235.49754 | Y24: =+W24-X24 -> -78.497539 | Z24: =+Y24*AC24 -> -2825.9114 | AB24: =+V24/20 -> 47.099508 | AC24: 36 | AD24: =+V24*AC24 -> 33911.646 | AE24: =+AD24/20 -> 1695.5823 | AF24: 0.12 | AG24: =+AE24*AF24 -> 203.46987 | AI24: =+IF(Z24<=0,Z24*AF24,0) -> -339.10937
A25: PT11003 | B25: PIPAS E PIC 36 U GRN 120G | C25: 74 | D25: 83 | E25: 96 | F25: 93 | G25: 71 | H25: 90 | I25: 101 | J25: 94 | K25: 108 | L25: 87 | M25: 103 | N25: 57 | O25: 137 | P25: 82 | Q25: 147 | R25: 106 | S25: =SUM(C25:R25) -> 1529 | U25: =+AVERAGE(C25:R25) -> 95.5625 | V25: =+U25*$V$47+U25 -> 102.49078 | W25: =+VLOOKUP(A25,'INVENTARIO ACTUAL'!$A$2:$E$40,5,FALSE) -> 45 | X25: =+V25/4 -> 25.622695 | Y25: =+W25-X25 -> 19.377305 | Z25: =+Y25*AC25 -> 697.58297 | AB25: =+V25/20 -> 5.1245391 | AC25: 36 | AD25: =+V25*AC25 -> 3689.6681 | AE25: =+AD25/20 -> 184.48341 | AF25: 0.12 | AG25: =+AE25*AF25 -> 22.138009 | AI25: =+IF(Z25<=0,Z25*AF25,0) -> 0
A26: PT11004 | B26: C PIPAS E PIC 36 U GRN 120G | C26: 41 | D26: 61 | E26: 91 | F26: 57 | G26: 13 | H26: 225 | I26: 12 | J26: 17 | K26: 11 | L26: 55 | M26: 54 | N26: 15 | O26: 60 | P26: 35 | Q26: 45 | R26: 35 | S26: =SUM(C26:R26) -> 827 | U26: =+AVERAGE(C26:R26) -> 51.6875 | V26: =+U26*$V$47+U26 -> 55.434844 | W26: =+VLOOKUP(A26,'INVENTARIO ACTUAL'!$A$2:$E$40,5,FALSE) -> 0 | X26: =+V26/4 -> 13.858711 | Y26: =+W26-X26 -> -13.858711 | Z26: =+Y26*AC26 -> -498.91359 | AB26: =+V26/20 -> 2.7717422 | AC26: 36 | AD26: =+V26*AC26 -> 1995.6544 | AE26: =+AD26/20 -> 99.782719 | AF26: 0.12 | AG26: =+AE26*AF26 -> 11.973926 | AI26: =+IF(Z26<=0,Z26*AF26,0) -> -59.869631
A27: PT12003 | B27: PIPAS E LIM 36 U GRN 120G | C27: 54 | D27: 29 | E27: 43 | F27: 37 | G27: 56 | H27: 24 | I27: 39 | J27: 41 | K27: 55 | L27: 15 | M27: 28 | N27: 18 | O27: 40 | P27: 30 | Q27: 24 | R27: 46 | S27: =SUM(C27:R27) -> 579 | U27: =+AVERAGE(C27:R27) -> 36.1875 | V27: =+U27*$V$47+U27 -> 38.811094 | W27: =+VLOOKUP(A27,'INVENTARIO ACTUAL'!$A$2:$E$40,5,FALSE) -> 47 | X27: =+V27/4 -> 9.7027734 | Y27: =+W27-X27 -> 37.297227 | Z27: =+Y27*AC27 -> 1342.7002 | AB27: =+V27/20 -> 1.9405547 | AC27: 36 | AD27: =+V27*AC27 -> 1397.1994 | AE27: =+AD27/20 -> 69.859969 | AF27: 0.12 | AG27: =+AE27*AF27 -> 8.3831962 | AI27: =+IF(Z27<=0,Z27*AF27,0) -> 0
A28: PT12004 | B28: C PIPAS E LIM 36 U GRN 120G | C28: 46 | D28: 49 | E28: 51 | F28: 45 | G28: 39 | H28: 43 | I28: 46 | J28: 52 | K28: 32 | L28: 41 | M28: 26 | N28: 0 | O28: 0 | S28: =SUM(C28:R28) -> 470 | U28: =+AVERAGE(C28:R28) -> 36.153846 | V28: =+U28*$V$47+U28 -> 38.775 | W28: =+VLOOKUP(A28,'INVENTARIO ACTUAL'!$A$2:$E$40,5,FALSE) -> 0 | X28: =+V28/4 -> 9.69375 | Y28: =+W28-X28 -> -9.69375 | Z28: =+Y28*AC28 -> -348.975 | AB28: =+V28/20 -> 1.93875 | AC28: 36 | AD28: =+V28*AC28 -> 1395.9 | AE28: =+AD28/20 -> 69.795 | AF28: 0.12 | AG28: =+AE28*AF28 -> 8.3754 | AI28: =+IF(Z28<=0,Z28*AF28,0) -> -41.877
A29: PT20003 | B29: PIPAS MGA VER 36 U GRN 120 G | C29: 710 | D29: 593 | E29: 684 | F29: 675 | G29: 591 | H29: 583 | I29: 663 | J29: 732 | K29: 641 | L29: 529 | M29: 574 | N29: 467 | O29: 733 | P29: 587 | Q29: 724 | R29: 686 | S29: =SUM(C29:R29) -> 10172 | U29: =+AVERAGE(C29:R29) -> 635.75 | V29: =+U29*$V$47+U29 -> 681.84187 | W29: =+VLOOKUP(A29,'INVENTARIO ACTUAL'!$A$2:$E$40,5,FALSE) -> 189 | X29: =+V29/4 -> 170.46047 | Y29: =+W29-X29 -> 18.539531 | Z29: =+Y29*AC29 -> 667.42313 | AB29: =+V29/20 -> 34.092094 | AC29: 36 | AD29: =+V29*AC29 -> 24546.307 | AE29: =+AD29/20 -> 1227.3154 | AF29: 0.12 | AG29: =+AE29*AF29 -> 147.27784 | AI29: =+IF(Z29<=0,Z29*AF29,0) -> 0
A30: PT20004 | B30: C PIPAS MGA VER 36 U GRN 120G | C30: 1079 | D30: 362 | E30: 483 | F30: 586 | G30: 916 | H30: 404 | I30: 708 | J30: 605 | K30: 582 | L30: 1242 | M30: 582 | N30: 370 | O30: 552 | P30: 738 | Q30: 1042 | R30: 626 | S30: =SUM(C30:R30) -> 10877 | U30: =+AVERAGE(C30:R30) -> 679.8125 | V30: =+U30*$V$47+U30 -> 729.09891 | W30: =+VLOOKUP(A30,'INVENTARIO ACTUAL'!$A$2:$E$40,5,FALSE) -> 206 | X30: =+V30/4 -> 182.27473 | Y30: =+W30-X30 -> 23.725273 | Z30: =+Y30*AC30 -> 854.10984 | AB30: =+V30/20 -> 36.454945 | AC30: 36 | AD30: =+V30*AC30 -> 26247.561 | AE30: =+AD30/20 -> 1312.378 | AF30: 0.12 | AG30: =+AE30*AF30 -> 157.48536 | AI30: =+IF(Z30<=0,Z30*AF30,0) -> 0
A31: PT21003 | B31: PIPAS MGA ACID-LEM 36 U GR 120 | C31: 361 | D31: 266 | E31: 336 | F31: 314 | G31: 308 | H31: 350 | I31: 302 | J31: 359 | K31: 338 | L31: 311 | M31: 300 | N31: 233 | O31: 438 | P31: 323 | Q31: 505 | R31: 487 | S31: =SUM(C31:R31) -> 5531 | U31: =+AVERAGE(C31:R31) -> 345.6875 | V31: =+U31*$V$47+U31 -> 370.74984 | W31: =+VLOOKUP(A31,'INVENTARIO ACTUAL'!$A$2:$E$40,5,FALSE) -> 92 | X31: =+V31/4 -> 92.687461 | Y31: =+W31-X31 -> -0.68746094 | Z31: =+Y31*AC31 -> -24.748594 | AB31: =+V31/20 -> 18.537492 | AC31: 36 | AD31: =+V31*AC31 -> 13346.994 | AE31: =+AD31/20 -> 667.34972 | AF31: 0.12 | AG31: =+AE31*AF31 -> 80.081966 | AI31: =+IF(Z31<=0,Z31*AF31,0) -> -2.9698312
A32: PT21004 | B32: C PIPAS MGA AC-LEM 36 U 120 GR | C32: 135 | D32: 79 | E32: 166 | F32: 183 | G32: 296 | H32: 151 | I32: 352 | J32: 180 | K32: 103 | L32: 177 | M32: 193 | N32: 186 | O32: 203 | P32: 174 | Q32: 224 | R32: 195 | S32: =SUM(C32:R32) -> 2997 | U32: =+AVERAGE(C32:R32) -> 187.3125 | V32: =+U32*$V$47+U32 -> 200.89266 | W32: =+VLOOKUP(A32,'INVENTARIO ACTUAL'!$A$2:$E$40,5,FALSE) -> 77 | X32: =+V32/4 -> 50.223164 | Y32: =+W32-X32 -> 26.776836 | Z32: =+Y32*AC32 -> 963.96609 | AB32: =+V32/20 -> 10.044633 | AC32: 36 | AD32: =+V32*AC32 -> 7232.1356 | AE32: =+AD32/20 -> 361.60678 | AF32: 0.12 | AG32: =+AE32*AF32 -> 43.392814 | AI32: =+IF(Z32<=0,Z32*AF32,0) -> 0
A33: PT30001 | B33: C PIPAS SPINNY SAL CAJA 24U120 | C33: 187 | D33: 159 | E33: 258 | F33: 210 | G33: 298 | H33: 208 | I33: 204 | J33: 151 | K33: 153 | L33: 239 | M33: 143 | N33: 164 | O33: 209 | P33: 136 | Q33: 185 | R33: 140 | S33: =SUM(C33:R33) -> 3044 | U33: =+AVERAGE(C33:R33) -> 190.25 | V33: =+U33*$V$47+U33 -> 204.04313 | W33: =+VLOOKUP(A33,'INVENTARIO ACTUAL'!$A$2:$E$40,5,FALSE) -> 30 | X33: =+V33/4 -> 51.010781 | Y33: =+W33-X33 -> -21.010781 | Z33: =+Y33*AC33 -> -504.25875 | AB33: =+V33/20 -> 10.202156 | AC33: 24 | AD33: =+V33*AC33 -> 4897.035 | AE33: =+AD33/20 -> 244.85175 | AF33: 0.12 | AG33: =+AE33*AF33 -> 29.38221 | AI33: =+IF(Z33<=0,Z33*AF33,0) -> -60.51105
A34: PT22003 | B34: PIPAS MGA MRAC-LIM 36 U 120 G | C34: 0 | D34: 0 | E34: 0 | F34: 0 | G34: 0 | H34: 249 | I34: 141 | J34: 145 | K34: 136 | L34: 101 | M34: 100 | N34: 74 | O34: 141 | P34: 120 | Q34: 200 | R34: 215 | S34: =SUM(C34:R34) -> 1622 | U34: =+AVERAGE(C34:R34) -> 101.375 | V34: =+U34*$V$47+U34 -> 108.72469 | W34: =+VLOOKUP(A34,'INVENTARIO ACTUAL'!$A$2:$E$40,5,FALSE) -> 73 | X34: =+V34/4 -> 27.181172 | Y34: =+W34-X34 -> 45.818828 | Z34: =+Y34*AC34 -> 1649.4778 | AB34: =+V34/20 -> 5.4362344 | AC34: 36 | AD34: =+V34*AC34 -> 3914.0887 | AE34: =+AD34/20 -> 195.70444 | AF34: 0.12 | AG34: =+AE34*AF34 -> 23.484532 | AI34: =+IF(Z34<=0,Z34*AF34,0) -> 0
A35: PT22004 | B35: C PIPAS MGA MRAC-LIM 36 U 120G | C35: 0 | D35: 0 | E35: 0 | F35: 0 | G35: 0 | H35: 25 | I35: 133 | J35: 89 | K35: 139 | L35: 144 | M35: 134 | N35: 170 | O35: 131 | P35: 117 | Q35: 133 | R35: 151 | S35: =SUM(C35:R35) -> 1366 | U35: =+AVERAGE(C35:R35) -> 85.375 | V35: =+U35*$V$47+U35 -> 91.564688 | W35: =+VLOOKUP(A35,'INVENTARIO ACTUAL'!$A$2:$E$40,5,FALSE) -> 30 | X35: =+V35/4 -> 22.891172 | Y35: =+W35-X35 -> 7.1088281 | Z35: =+Y35*AC35 -> 255.91781 | AB35: =+V35/20 -> 4.5782344 | AC35: 36 | AD35: =+V35*AC35 -> 3296.3288 | AE35: =+AD35/20 -> 164.81644 | AF35: 0.12 | AG35: =+AE35*AF35 -> 19.777973 | AI35: =+IF(Z35<=0,Z35*AF35,0) -> 0
C36: =+SUBTOTAL(9,C2:C35) -> 19300 | D36: =+SUBTOTAL(9,D2:D35) -> 13950 | E36: =+SUBTOTAL(9,E2:E35) -> 16039 | F36: =+SUBTOTAL(9,F2:F35) -> 15166.5 | G36: =+SUBTOTAL(9,G2:G35) -> 17769 | H36: =+SUBTOTAL(9,H2:H35) -> 15702 | I36: =+SUBTOTAL(9,I2:I35) -> 16581.5 | J36: =+SUBTOTAL(9,J2:J35) -> 16393.5 | ... S36: =+SUBTOTAL(9,S2:S35) -> 259090.5 | U36: =+SUBTOTAL(9,U2:U35) -> 16200.786 | V36: =+SUBTOTAL(9,V2:V35) -> 17375.343 | W36: =+SUBTOTAL(9,W2:W35) -> 5582 | X36: =+SUBTOTAL(9,X2:X35) -> 4343.8358 | Y36: =+SUBTOTAL(9,Y2:Y35) -> 1238.1642 | Z36: =+SUBTOTAL(9,Z2:Z35) -> 455793.68 | AB36: =+SUBTOTAL(9,AB2:AB35) -> 864.92961 | AD36: =+SUBTOTAL(9,AD2:AD35) -> 5442569.3 | AE36: =+SUBTOTAL(9,AE2:AE35) -> 272128.46 | AG36: =+SUBTOTAL(9,AG2:AG35) -> 5804.9108 | AI36: =+SUBTOTAL(9,AI2:AI35) -> -1345.462
A38: PT70001 | B38: POLVO MEGA LIMON PAC 60 SOL | C38: 133 | D38: 107 | E38: 162 | F38: 136 | G38: 124 | H38: 86 | I38: 73 | J38: 128 | K38: 161 | L38: 113 | M38: 161 | N38: 75 | O38: 124 | P38: 118 | Q38: 144 | R38: 148 | S38: =SUM(C38:R38) -> 1993 | U38: =+AVERAGE(C38:R38) -> 124.5625 | V38: =+U38*$V$47+U38 -> 133.59328 | W38: =+VLOOKUP(A38,'INVENTARIO ACTUAL'!$A$2:$E$40,5,FALSE) -> 51 | X38: =+V38/4 -> 33.39832 | Y38: =+W38-X38 -> 17.60168 | Z38: =+Y38*AC38 -> 42244.031 | AB38: =+V38/20 -> 6.6796641 | AC38: 2400 | AD38: =+V38*AC38 -> 320623.88 | AE38: =+AD38/20 -> 16031.194 | AF38: 0.002 | AG38: =+AE38*AF38 -> 32.062387 | AI38: =+IF(Z38<=0,Z38*AF38,0) -> 0
A39: PT70002 | B39: POLVO MEGA LIMON GRN | C39: 37 | D39: 23 | E39: 24 | F39: 20 | G39: 49 | H39: 55 | I39: 32 | J39: 28 | K39: 56 | L39: 56 | M39: 52 | N39: 44 | O39: 44 | P39: 40 | Q39: 40 | R39: 35 | S39: =SUM(C39:R39) -> 635 | U39: =+AVERAGE(C39:R39) -> 39.6875 | V39: =+U39*$V$47+U39 -> 42.564844 | W39: =+VLOOKUP(A39,'INVENTARIO ACTUAL'!$A$2:$E$40,5,FALSE) -> 106 | X39: =+V39/4 -> 10.641211 | Y39: =+W39-X39 -> 95.358789 | Z39: =+Y39*AC39 -> 228861.09 | AB39: =+V39/20 -> 2.1282422 | AC39: 2400 | AD39: =+V39*AC39 -> 102155.62 | AE39: =+AD39/20 -> 5107.7812 | AF39: 0.002 | AG39: =+AE39*AF39 -> 10.215563 | AI39: =+IF(Z39<=0,Z39*AF39,0) -> 0
A40: PT71001 | B40: POLVO MEGA MARACYA PAC 60 SOL | C40: 0 | D40: 0 | E40: 0 | F40: 0 | G40: 0 | H40: 0 | I40: 1 | J40: 0 | K40: 0 | L40: 0 | M40: 0 | N40: 0 | O40: 52 | P40: 70 | Q40: 70 | R40: 58 | S40: =SUM(C40:R40) -> 251 | U40: =+AVERAGE(C40:R40) -> 15.6875 | V40: =+U40*$V$47+U40 -> 16.824844 | W40: =+VLOOKUP(A40,'INVENTARIO ACTUAL'!$A$2:$E$40,5,FALSE) -> 45 | X40: =+V40/4 -> 4.2062109 | Y40: =+W40-X40 -> 40.793789 | Z40: =+Y40*AC40 -> 97905.094 | AB40: =+V40/20 -> 0.84124219 | AC40: 2400 | AD40: =+V40*AC40 -> 40379.625 | AE40: =+AD40/20 -> 2018.9813 | AF40: 0.002 | AG40: =+AE40*AF40 -> 4.0379625 | AI40: =+IF(Z40<=0,Z40*AF40,0) -> 0
A41: PT71002 | B41: POLVO MEGA MARACUYA GRN | C41: 13 | D41: 15 | E41: 15 | F41: 15 | G41: 27 | H41: 89 | I41: 77 | J41: 17 | K41: 76 | L41: 74 | M41: 82 | N41: 20 | O41: 38 | P41: 55 | Q41: 48 | R41: 77 | S41: =SUM(C41:R41) -> 738 | U41: =+AVERAGE(C41:R41) -> 46.125 | V41: =+U41*$V$47+U41 -> 49.469062 | W41: =+VLOOKUP(A41,'INVENTARIO ACTUAL'!$A$2:$E$40,5,FALSE) -> 20 | X41: =+V41/4 -> 12.367266 | Y41: =+W41-X41 -> 7.6327344 | Z41: =+Y41*AC41 -> 18318.562 | AB41: =+V41/20 -> 2.4734531 | AC41: 2400 | AD41: =+V41*AC41 -> 118725.75 | AE41: =+AD41/20 -> 5936.2875 | AF41: 0.002 | AG41: =+AE41*AF41 -> 11.872575 | AI41: =+IF(Z41<=0,Z41*AF41,0) -> 0
...

Sheet ENVIAR
A1: Item ID | B1: Item Description | C1: STOCK ACTUAL BODEGA | D1: PACAS PROMEDIO MENSUAL | E1: STOK SEMANAL PACAS PROMEDIO | F1: DIF PACAS
A2: PT10001 | B2: PIPAS E SAL - PACAS 400 U T-10 | C2: =+VLOOKUP(A2,'ANALISIS PROD'!$A$2:$Y$46,22,FALSE) -> 785.10352 | D2: =+VLOOKUP(A2,'ANALISIS PROD'!$A$2:$Y$46,21,FALSE) -> 732.03125 | E2: =+VLOOKUP(A2,'ANALISIS PROD'!$A$2:$Y$46,23,FALSE) -> 235.5 | F2: =+C2-E2 -> 549.60352
A3: PT10002 | B3: PIPAS E SAL - PACAS 400 U T-20 | C3: =+VLOOKUP(A3,'ANALISIS PROD'!$A$2:$Y$46,22,FALSE) -> 594.86883 | D3: =+VLOOKUP(A3,'ANALISIS PROD'!$A$2:$Y$46,21,FALSE) -> 554.65625 | E3: =+VLOOKUP(A3,'ANALISIS PROD'!$A$2:$Y$46,23,FALSE) -> 223.5 | F3: =+C3-E3 -> 371.36883
A4: PT11001 | B4: PIPAS E PIC - PACAS 400 U T-10 | C4: =+VLOOKUP(A4,'ANALISIS PROD'!$A$2:$Y$46,22,FALSE) -> 57.345234 | D4: =+VLOOKUP(A4,'ANALISIS PROD'!$A$2:$Y$46,21,FALSE) -> 53.46875 | E4: =+VLOOKUP(A4,'ANALISIS PROD'!$A$2:$Y$46,23,FALSE) -> 71 | F4: =+C4-E4 -> -13.654766
A5: PT11002 | B5: PIPAS E PIC - PACAS 400 U T-20 | C5: =+VLOOKUP(A5,'ANALISIS PROD'!$A$2:$Y$46,22,FALSE) -> 10.859063 | D5: =+VLOOKUP(A5,'ANALISIS PROD'!$A$2:$Y$46,21,FALSE) -> 10.125 | E5: =+VLOOKUP(A5,'ANALISIS PROD'!$A$2:$Y$46,23,FALSE) -> 10 | F5: =+C5-E5 -> 0.8590625
A6: PT12001 | B6: PIPAS E LIM - PACAS 400 U T-10 | C6: =+VLOOKUP(A6,'ANALISIS PROD'!$A$2:$Y$46,22,FALSE) -> 502.66734 | D6: =+VLOOKUP(A6,'ANALISIS PROD'!$A$2:$Y$46,21,FALSE) -> 468.6875 | E6: =+VLOOKUP(A6,'ANALISIS PROD'!$A$2:$Y$46,23,FALSE) -> 179 | F6: =+C6-E6 -> 323.66734
A7: PT12002 | B7: PIPAS E LIM - PACAS 400 U T-20 | C7: =+VLOOKUP(A7,'ANALISIS PROD'!$A$2:$Y$46,22,FALSE) -> 93.910781 | D7: =+VLOOKUP(A7,'ANALISIS PROD'!$A$2:$Y$46,21,FALSE) -> 87.5625 | E7: =+VLOOKUP(A7,'ANALISIS PROD'!$A$2:$Y$46,23,FALSE) -> 67 | F7: =+C7-E7 -> 26.910781
A8: PT13001 | B8: PIPAS E MAR - PACAS 400 U T-10 | C8: =+VLOOKUP(A8,'ANALISIS PROD'!$A$2:$Y$46,22,FALSE) -> 135.33609 | D8: =+VLOOKUP(A8,'ANALISIS PROD'!$A$2:$Y$46,21,FALSE) -> 126.1875 | E8: =+VLOOKUP(A8,'ANALISIS PROD'!$A$2:$Y$46,23,FALSE) -> 83 | F8: =+C8-E8 -> 52.336094
A9: PT13002 | B9: PIPAS E MAR - PACAS 400 U T-20 | C9: =+VLOOKUP(A9,'ANALISIS PROD'!$A$2:$Y$46,22,FALSE) -> 0 | D9: =+VLOOKUP(A9,'ANALISIS PROD'!$A$2:$Y$46,21,FALSE) -> 0 | E9: =+VLOOKUP(A9,'ANALISIS PROD'!$A$2:$Y$46,23,FALSE) -> 0 | F9: =+C9-E9 -> 0
A10: PT20001 | B10: PIPAS MGA VER-PACAS 400 T-10 | C10: =+VLOOKUP(A10,'ANALISIS PROD'!$A$2:$Y$46,22,FALSE) -> 1181.3588 | D10: =+VLOOKUP(A10,'ANALISIS PROD'!$A$2:$Y$46,21,FALSE) -> 1101.5 | E10: =+VLOOKUP(A10,'ANALISIS PROD'!$A$2:$Y$46,23,FALSE) -> 497.5 | F10: =+C10-E10 -> 683.85875
A11: PT20002 | B11: PIPAS MGA VER-PACAS 400 T-20 | C11: =+VLOOKUP(A11,'ANALISIS PROD'!$A$2:$Y$46,22,FALSE) -> 3068.8917 | D11: =+VLOOKUP(A11,'ANALISIS PROD'!$A$2:$Y$46,21,FALSE) -> 2861.4375 | E11: =+VLOOKUP(A11,'ANALISIS PROD'!$A$2:$Y$46,23,FALSE) -> 1225 | F11: =+C11-E11 -> 1843.8917
A12: PT20013 | B12: PIPAS MGA VERDE P 400 T20+2 | C12: =+VLOOKUP(A12,'ANALISIS PROD'!$A$2:$Y$46,22,FALSE) -> 76.750781 | D12: =+VLOOKUP(A12,'ANALISIS PROD'!$A$2:$Y$46,21,FALSE) -> 71.5625 | E12: =+VLOOKUP(A12,'ANALISIS PROD'!$A$2:$Y$46,23,FALSE) -> 62 | F12: =+C12-E12 -> 14.750781
A13: PT21001 | B13: PIPAS MGA ACID-LEM-PAC 400 T10 | C13: =+VLOOKUP(A13,'ANALISIS PROD'!$A$2:$Y$46,22,FALSE) -> 1724.9822 | D13: =+VLOOKUP(A13,'ANALISIS PROD'!$A$2:$Y$46,21,FALSE) -> 1608.375 | E13: =+VLOOKUP(A13,'ANALISIS PROD'!$A$2:$Y$46,23,FALSE) -> 389 | F13: =+C13-E13 -> 1335.9822
... A21: PT23002 | B21: PIPAS MGA PIC-LIM-PAC 400 T-20 | C21: =+VLOOKUP(A21,'ANALISIS PROD'!$A$2:$Y$46,22,FALSE) -> 531.12211 | D21: =+VLOOKUP(A21,'ANALISIS PROD'!$A$2:$Y$46,21,FALSE) -> 495.21875 | E21: =+VLOOKUP(A21,'ANALISIS PROD'!$A$2:$Y$46,23,FALSE) -> 162.5 | F21: =+C21-E21 -> 368.62211
B23: TOTAL PACAS 19 GR | C23: =SUM(C2:C21) -> 13300.013 | D23: =SUM(D2:D21) -> 12400.945 | E23: =SUM(E2:E21) -> 4501
A25: PT10003 | B25: PIPAS E SAL 36 U GRN 120G | C25: =+VLOOKUP(A25,'ANALISIS PROD'!$A$2:$Y$46,22,FALSE) -> 510.91219 | D25: =+VLOOKUP(A25,'ANALISIS PROD'!$A$2:$Y$46,21,FALSE) -> 476.375 | E25: =+VLOOKUP(A25,'ANALISIS PROD'!$A$2:$Y$46,23,FALSE) -> 135 | F25: =+C25-E25 -> 375.91219
A26: PT10004 | B26: C PIPAS E SAL 36 U GRN 120G | C26: =+VLOOKUP(A26,'ANALISIS PROD'!$A$2:$Y$46,22,FALSE) -> 941.99016 | D26: =+VLOOKUP(A26,'ANALISIS PROD'!$A$2:$Y$46,21,FALSE) -> 878.3125 | E26: =+VLOOKUP(A26,'ANALISIS PROD'!$A$2:$Y$46,23,FALSE) -> 157 | F26: =+C26-E26 -> 784.99016
A27: PT11003 | B27: PIPAS E PIC 36 U GRN 120G | C27: =+VLOOKUP(A27,'ANALISIS PROD'!$A$2:$Y$46,22,FALSE) -> 102.49078 | D27: =+VLOOKUP(A27,'ANALISIS PROD'!$A$2:$Y$46,21,FALSE) -> 95.5625 | E27: =+VLOOKUP(A27,'ANALISIS PROD'!$A$2:$Y$46,23,FALSE) -> 45 | F27: =+C27-E27 -> 57.490781
A28: PT11004 | B28: C PIPAS E PIC 36 U GRN 120G | C28: =+VLOOKUP(A28,'ANALISIS PROD'!$A$2:$Y$46,22,FALSE) -> 55.434844 | D28: =+VLOOKUP(A28,'ANALISIS PROD'!$A$2:$Y$46,21,FALSE) -> 51.6875 | E28: =+VLOOKUP(A28,'ANALISIS PROD'!$A$2:$Y$46,23,FALSE) -> 0 | F28: =+C28-E28 -> 55.434844
A29: PT12003 | B29: PIPAS E LIM 36 U GRN 120G | C29: =+VLOOKUP(A29,'ANALISIS PROD'!$A$2:$Y$46,22,FALSE) -> 38.811094 | D29: =+VLOOKUP(A29,'ANALISIS PROD'!$A$2:$Y$46,21,FALSE) -> 36.1875 | E29: =+VLOOKUP(A29,'ANALISIS PROD'!$A$2:$Y$46,23,FALSE) -> 47 | F29: =+C29-E29 -> -8.1889063
A30: PT12004 | B30: C PIPAS E LIM 36 U GRN 120G | C30: =+VLOOKUP(A30,'ANALISIS PROD'!$A$2:$Y$46,22,FALSE) -> 38.775 | D30: =+VLOOKUP(A30,'ANALISIS PROD'!$A$2:$Y$46,21,FALSE) -> 36.153846 | E30: =+VLOOKUP(A30,'ANALISIS PROD'!$A$2:$Y$46,23,FALSE) -> 0 | F30: =+C30-E30 -> 38.775
A31: PT20003 | B31: PIPAS MGA VER 36 U GRN 120 G | C31: =+VLOOKUP(A31,'ANALISIS PROD'!$A$2:$Y$46,22,FALSE) -> 681.84187 | D31: =+VLOOKUP(A31,'ANALISIS PROD'!$A$2:$Y$46,21,FALSE) -> 635.75 | E31: =+VLOOKUP(A31,'ANALISIS PROD'!$A$2:$Y$46,23,FALSE) -> 189 | F31: =+C31-E31 -> 492.84187
A32: PT20004 | B32: C PIPAS MGA VER 36 U GRN 120G | C32: =+VLOOKUP(A32,'ANALISIS PROD'!$A$2:$Y$46,22,FALSE) -> 729.09891 | D32: =+VLOOKUP(A32,'ANALISIS PROD'!$A$2:$Y$46,21,FALSE) -> 679.8125 | E32: =+VLOOKUP(A32,'ANALISIS PROD'!$A$2:$Y$46,23,FALSE) -> 206 | F32: =+C32-E32 -> 523.09891
A33: PT21003 | B33: PIPAS MGA ACID-LEM 36 U GR 120 | C33: =+VLOOKUP(A33,'ANALISIS PROD'!$A$2:$Y$46,22,FALSE) -> 370.74984 | D33: =+VLOOKUP(A33,'ANALISIS PROD'!$A$2:$Y$46,21,FALSE) -> 345.6875 | E33: =+VLOOKUP(A33,'ANALISIS PROD'!$A$2:$Y$46,23,FALSE) -> 92 | F33: =+C33-E33 -> 278.74984
A34: PT21004 | B34: C PIPAS MGA AC-LEM 36 U 120 GR | C34: =+VLOOKUP(A34,'ANALISIS PROD'!$A$2:$Y$46,22,FALSE) -> 200.89266 | D34: =+VLOOKUP(A34,'ANALISIS PROD'!$A$2:$Y$46,21,FALSE) -> 187.3125 | E34: =+VLOOKUP(A34,'ANALISIS PROD'!$A$2:$Y$46,23,FALSE) -> 77 | F34: =+C34-E34 -> 123.89266
A35: PT30001 | B35: C PIPAS SPINNY SAL CAJA 24U120 | C35: =+VLOOKUP(A35,'ANALISIS PROD'!$A$2:$Y$46,22,FALSE) -> 204.04313 | D35: =+VLOOKUP(A35,'ANALISIS PROD'!$A$2:$Y$46,21,FALSE) -> 190.25 | E35: =+VLOOKUP(A35,'ANALISIS PROD'!$A$2:$Y$46,23,FALSE) -> 30 | F35: =+C35-E35 -> 174.04313
A36: PT22003 | B36: PIPAS MGA MRAC-LIM 36 U 120 G | C36: =+VLOOKUP(A36,'ANALISIS PROD'!$A$2:$Y$46,22,FALSE) -> 108.72469 | D36: =+VLOOKUP(A36,'ANALISIS PROD'!$A$2:$Y$46,21,FALSE) -> 101.375 | E36: =+VLOOKUP(A36,'ANALISIS PROD'!$A$2:$Y$46,23,FALSE) -> 73 | F36: =+C36-E36 -> 35.724688
A37: PT22004 | B37: C PIPAS MGA MRAC-LIM 36 U 120G | C37: =+VLOOKUP(A37,'ANALISIS PROD'!$A$2:$Y$46,22,FALSE) -> 91.564688 | D37: =+VLOOKUP(A37,'ANALISIS PROD'!$A$2:$Y$46,21,FALSE) -> 85.375 | E37: =+VLOOKUP(A37,'ANALISIS PROD'!$A$2:$Y$46,23,FALSE) -> 30 | F37: =+C37-E37 -> 61.564688
B39: TOTAL PACAS 120GR | C39: =SUM(C25:C37) -> 4075.3298 | D39: =SUM(D25:D37) -> 3799.8413 | E39: =SUM(E25:E37) -> 1081
A41: PT70001 | B41: POLVO MEGA LIMON PAC 60 SOL | C41: =+VLOOKUP(A41,'ANALISIS PROD'!$A$2:$Y$46,22,FALSE) -> 133.59328 | D41: =+VLOOKUP(A41,'ANALISIS PROD'!$A$2:$Y$46,21,FALSE) -> 124.5625 | E41: =+VLOOKUP(A41,'ANALISIS PROD'!$A$2:$Y$46,23,FALSE) -> 51 | F41: =+C41-E41 -> 82.593281
A42: PT70002 | B42: POLVO MEGA LIMON GRN | C42: =+VLOOKUP(A42,'ANALISIS PROD'!$A$2:$Y$46,22,FALSE) -> 42.564844 | D42: =+VLOOKUP(A42,'ANALISIS PROD'!$A$2:$Y$46,21,FALSE) -> 39.6875 | E42: =+VLOOKUP(A42,'ANALISIS PROD'!$A$2:$Y$46,23,FALSE) -> 106 | F42: =+C42-E42 -> -63.435156
A43: PT71001 | B43: POLVO MEGA MARACYA PAC 60 SOL | C43: =+VLOOKUP(A43,'ANALISIS PROD'!$A$2:$Y$46,22,FALSE) -> 16.824844 | D43: =+VLOOKUP(A43,'ANALISIS PROD'!$A$2:$Y$46,21,FALSE) -> 15.6875 | E43: =+VLOOKUP(A43,'ANALISIS PROD'!$A$2:$Y$46,23,FALSE) -> 45 | F43: =+C43-E43 -> -28.175156
A44: PT71002 | B44: POLVO MEGA MARACUYA GRN | C44: =+VLOOKUP(A44,'ANALISIS PROD'!$A$2:$Y$46,22,FALSE) -> 49.469062 | D44: =+VLOOKUP(A44,'ANALISIS PROD'!$A$2:$Y$46,21,FALSE) -> 46.125 | E44: =+VLOOKUP(A44,'ANALISIS PROD'!$A$2:$Y$46,23,FALSE) -> 20 | F44: =+C44-E44 -> 29.469062
A45: PT72001 | B45: POLVO MGA MIX LIM-MARC 60 SOL | C45: =+VLOOKUP(A45,'ANALISIS PROD'!$A$2:$Y$46,22,FALSE) -> 652.48219 | D45: =+VLOOKUP(A45,'ANALISIS PROD'!$A$2:$Y$46,21,FALSE) -> 608.375 | E45: =+VLOOKUP(A45,'ANALISIS PROD'!$A$2:$Y$46,23,FALSE) -> 127 | F45: =+C45-E45 -> 525.48219
C47: =SUM(C41:C46) -> 894.93422 | D47: =SUM(D41:D46) -> 834.4375 | E47: =SUM(E41:E46) -> 349

Sheet INVENTARIO ACTUAL
A1: ITEM | B1: DESCRIPCION | C1: INGRESOS | D1: DESPACHOS | E1: SALDO
A2: PT10001 | B2: PIPAS E SAL - PACAS 400 U T-10 | C2: 2874 | D2: 2638,5 | E2: 235.5 | F2: =+VLOOKUP(A2,'ANALISIS PROD'!$A$2:$A$43,1,FALSE) -> PT10001 | I2: ITEM | J2: DESCRIPCION | K2: INGRESOS | L2: DESPACHOS | M2: SALDO
A3: PT10002 | B3: PIPAS E SAL - PACAS 400 U T-20 | C3: 2398,5 | D3: 2175 | E3: 223.5 | F3: =+VLOOKUP(A3,'ANALISIS PROD'!$A$2:$A$43,1,FALSE) -> PT10002 | I3: PT10001 | J3: PIPAS E SAL - PACAS 400 U T-10 | K3: 392,5 | L3: 154,5 | M3: 238
A4: PT10003 | B4: PIPAS E SAL 36 U GRN 120G | C4: 2278 | D4: 2143 | E4: 135 | F4: =+VLOOKUP(A4,'ANALISIS PROD'!$A$2:$A$43,1,FALSE) -> PT10003 | I4: PT10002 | J4: PIPAS E SAL - PACAS 400 U T-20 | K4: 297,5 | L4: 183,5 | M4: 114
A5: PT10004 | B5: C PIPAS E SAL 36 U GRN 120G | C5: 4067 | D5: 3910 | E5: 157 | F5: =+VLOOKUP(A5,'ANALISIS PROD'!$A$2:$A$43,1,FALSE) -> PT10004 | I5: PT10003 | J5: PIPAS E SAL 36 U GRN 120G | K5: 305 | L5: 217 | M5: 87
A6: PT10009 | B6: PIPAS E SAL DEGUSTACION | C6: 444 | D6: 375 | E6: 69 | F6: =+VLOOKUP(A6,'ANALISIS PROD'!$A$2:$A$43,1,FALSE) -> #N/A | I6: PT10004 | J6: C PIPAS E SAL 36 U GRN 120G | K6: 327 | L6: 147 | M6: 180
A7: PT11001 | B7: PIPAS E PIC - PACAS 400 U T-10 | C7: 220 | D7: 149 | E7: 71 | F7: =+VLOOKUP(A7,'ANALISIS PROD'!$A$2:$A$43,1,FALSE) -> PT11001 | I7: PT10009 | J7: PIPAS E SAL DEGUSTACION | K7: 78 | L7: 38 | M7: 40
A8: PT11002 | B8: PIPAS E PIC - PACAS 400 U T-20 | C8: 41 | D8: 31 | E8: 10 | F8: =+VLOOKUP(A8,'ANALISIS PROD'!$A$2:$A$43,1,FALSE) -> PT11002 | I8: PT11001 | J8: PIPAS E PIC - PACAS 400 U T-10 | K8: 75 | L8: 13 | M8: 62
A9: PT11003 | B9: PIPAS E PIC 36 U GRN 120G | C9: 528 | D9: 483 | E9: 45 | F9: =+VLOOKUP(A9,'ANALISIS PROD'!$A$2:$A$43,1,FALSE) -> PT11003 | I9: PT11002 | J9: PIPAS E PIC - PACAS 400 U T-20 | K9: 1 | L9: 1 | M9: 0
A10: PT11004 | B10: C PIPAS E PIC 36 U GRN 120G | C10: 180 | D10: 180 | E10: 0 | F10: =+VLOOKUP(A10,'ANALISIS PROD'!$A$2:$A$43,1,FALSE) -> PT11004 | I10: PT11003 | J10: PIPAS E PIC 36 U GRN 120G | K10: 59 | L10: 41 | M10: 17
A11: PT12001 | B11: PIPAS E LIM - PACAS 400 U T-10 | C11: 1812 | D11: 1633 | E11: 179 | F11: =+VLOOKUP(A11,'ANALISIS PROD'!$A$2:$A$43,1,FALSE) -> PT12001 | I11: PT11004 | J11: C PIPAS E PIC 36 U GRN 120G | K11: 20 | L11: 20 | M11: 0
A12: PT12002 | B12: PIPAS E LIM - PACAS 400 U T-20 | C12: 353 | D12: 286 | E12: 67 | F12: =+VLOOKUP(A12,'ANALISIS PROD'!$A$2:$A$43,1,FALSE) -> PT12002 | I12: PT12001 | J12: PIPAS E LIM - PACAS 400 U T-10 | K12: 240 | L12: 75 | M12: 165
A13: PT12003 | B13: PIPAS E LIM 36 U GRN 120G | C13: 192 | D13: 145 | E13: 47 | F13: =+VLOOKUP(A13,'ANALISIS PROD'!$A$2:$A$43,1,FALSE) -> PT12003 | I13: PT12002 | J13: PIPAS E LIM - PACAS 400 U T-20 | K13: 70 | L13: 19 | M13: 51
A14: PT12004 | B14: C PIPAS E LIM 36 U GRN 120G | C14: 16 | D14: 16 | E14: 0 | F14: =+VLOOKUP(A14,'ANALISIS PROD'!$A$2:$A$43,1,FALSE) -> PT12004 | I14: PT12003 | J14: PIPAS E LIM 36 U GRN 120G | K14: 52 | L14: 15 | M14: 37
A15: PT13001 | B15: PIPAS E MAR - PACAS 400 U T-10 | C15: 463 | D15: 380 | E15: 83 | F15: =+VLOOKUP(A15,'ANALISIS PROD'!$A$2:$A$43,1,FALSE) -> PT13001 | I15: PT12004 | J15: C PIPAS E LIM 36 U GRN 120G | K15: 16 | L15: 16 | M15: 0
A16: PT20001 | B16: PIPAS MGA VER-PACAS 400 T-10 | C16: 4734,5 | D16: 4237 | E16: 497.5 | F16: =+VLOOKUP(A16,'ANALISIS PROD'!$A$2:$A$43,1,FALSE) -> PT20001 | I16: PT13001 | J16: PIPAS E MAR - PACAS 400 U T-10 | K16: 88 | L16: 39 | M16: 49
A17: PT20002 | B17: PIPAS MGA VER-PACAS 400 T-20 | C17: 12670 | D17: 11445 | E17: 1225 | F17: =+VLOOKUP(A17,'ANALISIS PROD'!$A$2:$A$43,1,FALSE) -> PT20002 | I17: PT20001 | J17: PIPAS MGA VER-PACAS 400 T-10 | K17: 650 | L17: 403,5 | M17: 246,5
A18: PT20003 | B18: PIPAS MGA VER 36 U GRN 120 G | C18: 3021 | D18: 2832 | E18: 189 | F18: =+VLOOKUP(A18,'ANALISIS PROD'!$A$2:$A$43,1,FALSE) -> PT20003 | I18: PT20002 | J18: PIPAS MGA VER-PACAS 400 T-20 | K18: 1657 | L18: 944 | M18: 713
A19: PT20004 | B19: C PIPAS MGA VER 36 U GRN 120G | C19: 3221 | D19: 3017 | E19: 206 | F19: =+VLOOKUP(A19,'ANALISIS PROD'!$A$2:$A$43,1,FALSE) -> PT20004 | I19: PT20003 | J19: PIPAS MGA VER 36 U GRN 120 G | K19: 312 | L19: 276 | M19: 36
A20: PT20006 | B20: PIPAS MGA VER PACA 400 U GRN | C20: 85 | D20: 74 | E20: 11 | F20: =+VLOOKUP(A20,'ANALISIS PROD'!$A$2:$A$43,1,FALSE) -> PT20006 | I20: PT20004 | J20: C PIPAS MGA VER 36 U GRN 120G | K20: 192 | L20: 154 | M20: 38
A21: PT20008 | B21: PIPAS MGA VER-COLOM 400 T-20 | C21: 491 | D21: 451 | E21: 40 | F21: =+VLOOKUP(A21,'ANALISIS PROD'!$A$2:$A$43,1,FALSE) -> #N/A | I21: PT20006 | J21: PIPAS MGA VER PACA 400 U GRN | K21: 35 | L21: 15 | M21: 20
A22: PT21001 | B22: PIPAS MGA ACID-LEM-PAC 400 T10 | C22: 6993,5 | D22: 6604,5 | E22: 389 | F22: =+VLOOKUP(A22,'ANALISIS PROD'!$A$2:$A$43,1,FALSE) -> PT21001 | I22: PT20008 | J22: PIPAS MGA VER-COLOM 400 T-20 | K22: 59 | L22: 30 | M22: 29
A23: PT21002 | B23: PIPAS MGA ACID-LEM-PAC 400 T20 | C23: 9914 | D23: 9263,5 | E23: 650.5 | F23: =+VLOOKUP(A23,'ANALISIS PROD'!$A$2:$A$43,1,FALSE) -> PT21002 | I23: PT21001 | J23: PIPAS MGA ACID-LEM-PAC 400 T10 | K23: 834,5 | L23: 513 | M23: 321,5
A24: PT21003 | B24: PIPAS MGA ACID-LEM 36 U GR 120 | C24: 1915 | D24: 1823 | E24: 92 | F24: =+VLOOKUP(A24,'ANALISIS PROD'!$A$2:$A$43,1,FALSE) -> PT21003 | I24: PT21002 | J24: PIPAS MGA ACID-LEM-PAC 400 T20 | K24: 1282 | L24: 834 | M24: 448
A25: PT21004 | B25: C PIPAS MGA AC-LEM 36 U 120 GR | C25: 893 | D25: 816 | E25: 77 | F25: =+VLOOKUP(A25,'ANALISIS PROD'!$A$2:$A$43,1,FALSE) -> PT21004 | I25: PT21003 | J25: PIPAS MGA ACID-LEM 36 U GR 120 | K25: 249 | L25: 208 | M25: 41
A26: PT22001 | B26: PIPAS MGA MRAC-LIM-PAC 400 T10 | C26: 3457 | D26: 3269,5 | E26: 187.5 | F26: =+VLOOKUP(A26,'ANALISIS PROD'!$A$2:$A$43,1,FALSE) -> PT22001 | I26: PT21004 | J26: C PIPAS MGA AC-LEM 36 U 120 GR | K26: 50 | L26: 32 | M26: 18
A27: PT22002 | B27: PIPAS MGA MRAC-LIM-PAC 400 T20 | C27: 2970 | D27: 2720 | E27: 250 | F27: =+VLOOKUP(A27,'ANALISIS PROD'!$A$2:$A$43,1,FALSE) -> PT22002 | I27: PT22001 | J27: PIPAS MGA MRAC-LIM-PAC 400 T10 | K27: 369 | L27: 223,5 | M27: 145,5
A28: PT23001 | B28: PIPAS MGA PIC-LIM-PAC 400 T-10 | C28: 2129 | D28: 1992 | E28: 137 | F28: =+VLOOKUP(A28,'ANALISIS PROD'!$A$2:$A$43,1,FALSE) -> PT23001 | I28: PT22002 | J28: PIPAS MGA MRAC-LIM-PAC 400 T20 | K28: 379 | L28: 220 | M28: 159
A29: PT23002 | B29: PIPAS MGA PIC-LIM-PAC 400 T-20 | C29: 2447 | D29: 2284,5 | E29: 162.5 | F29: =+VLOOKUP(A29,'ANALISIS PROD'!$A$2:$A$43,1,FALSE) -> PT23002 | I29: PT23001 | J29: PIPAS MGA PIC-LIM-PAC 400 T-10 | K29: 327 | L29: 108,5 | M29: 218,5
A30: PT30001 | B30: C PIPAS SPINNY SAL CAJA 24U120 | C30: 718 | D30: 688 | E30: 30 | F30: =+VLOOKUP(A30,'ANALISIS PROD'!$A$2:$A$43,1,FALSE) -> PT30001 | I30: PT23002 | J30: PIPAS MGA PIC-LIM-PAC 400 T-20 | K30: 293 | L30: 212,5 | M30: 80,5
A31: PT70001 | B31: POLVO MEGA LIMON PAC 60 SOL | C31: 733 | D31: 682 | E31: 51 | F31: =+VLOOKUP(A31,'ANALISIS PROD'!$A$2:$A$43,1,FALSE) -> PT70001 | I31: PT30001 | J31: C PIPAS SPINNY SAL CAJA 24U120 | K31: 90 | L31: 72 | M31: 18
A32: PT70002 | B32: POLVO MEGA LIMON GRN | C32: 310 | D32: 204 | E32: 106 | F32: =+VLOOKUP(A32,'ANALISIS PROD'!$A$2:$A$43,1,FALSE) -> PT70002 | I32: PT70001 | J32: POLVO MEGA LIMON PAC 60 SOL | K32: 123 | L32: 64 | M32: 59
A33: PT71001 | B33: POLVO MEGA MARACYA PAC 60 SOL | C33: 323 | D33: 278 | E33: 45 | F33: =+VLOOKUP(A33,'ANALISIS PROD'!$A$2:$A$43,1,FALSE) -> PT71001 | I33: PT70002 | J33: POLVO MEGA LIMON GRN | K33: 45 | L33: 28 | M33: 17
A34: PT71002 | B34: POLVO MEGA MARACUYA GRN | C34: 289 | D34: 269 | E34: 20 | F34: =+VLOOKUP(A34,'ANALISIS PROD'!$A$2:$A$43,1,FALSE) -> PT71002 | I34: PT71001 | J34: POLVO MEGA MARACYA PAC 60 SOL | K34: 123 | L34: 26 | M34: 97
A35: PT72001 | B35: POLVO MGA MIX LIM-MARC 60 SOL | C35: 2951 | D35: 2823 | E35: 127 | F35: =+VLOOKUP(A35,'ANALISIS PROD'!$A$2:$A$43,1,FALSE) -> PT72001 | I35: PT71002 | J35: POLVO MEGA MARACUYA GRN | K35: 60 | L35: 41 | M35: 19
A36: PT21005 | B36: PIPAS MGA ACID-LEM PACA 400 GR | C36: 3 | D36: 0 | E36: 3 | F36: =+VLOOKUP(A36,'ANALISIS PROD'!$A$2:$A$43,1,FALSE) -> PT21005 | I36: PT72001 | J36: POLVO MGA MIX LIM-MARC 60 SOL | K36: 306 | L36: 303 | M36: 3
A37: PT22003 | B37: PIPAS MGA MRAC-LIM 36 U 120 G | C37: 789 | D37: 716 | E37: 73 | F37: =+VLOOKUP(A37,'ANALISIS PROD'!$A$2:$A$43,1,FALSE) -> PT22003 | I37: PT21005 | J37: PIPAS MGA ACID-LEM PACA 400 GR | K37: 3 | L37: 0 | M37: 3
A38: PT22004 | B38: C PIPAS MGA MRAC-LIM 36 U 120G | C38: 593 | D38: 561 | E38: 30 | F38: =+VLOOKUP(A38,'ANALISIS PROD'!$A$2:$A$43,1,FALSE) -> PT22004 | I38: PT22003 | J38: PIPAS MGA MRAC-LIM 36 U 120 G | K38: 108 | L38: 65 | M38: 43
A39: PT21006 | B39: PIPAS MGA ACID-LEM P 400 T20+2 | C39: 1201 | D39: 1144 | E39: 57 | F39: =+VLOOKUP(A39,'ANALISIS PROD'!$A$2:$A$43,1,FALSE) -> PT21006 | I39: PT22004 | J39: C PIPAS MGA MRAC-LIM 36 U 120G | K39: 54 | L39: 20 | M39: 34
A40: PT20013 | B40: PIPAS MGA VERDE P 400 T20+2 | C40: 1103 | D40: 1041 | E40: 62 | F40: =+VLOOKUP(A40,'ANALISIS PROD'!$A$2:$A$43,1,FALSE) -> PT20013 | I40: PT21006 | J40: PIPAS MGA ACID-LEM P 400 T20+2 | K40: 189 | L40: 127 | M40: 62
...

Sheet TIRAS X H
A1: T-20 | B1: 19 | C1: T-10 | D1: 18
B2: 19 | D2: 18
B3: 18 | D3: 20
B4: 12 | D4: 20
A5: PROMEDIO X MINUTO | B5: =+AVERAGE(B1:B4) -> 17 | D5: =+AVERAGE(D1:D4) -> 19
A6: POR HORA | B6: =+B5*60 -> 1020 | D6: =+D5*60 -> 1140
A7: EN 8 HORAS | B7: =+B6*8 -> 8160 | D7: =+D6*8 -> 9120
A8: (4) PERSONAS TIRAS DIARIAS | B8: =+B7*4 -> 32640 | D8: =+D7*4 -> 36480
A9: PRODUCCION SEMANAL | B9: =+B8*5 -> 163200 | D9: =+D8*5 -> 182400
A10: LO QUE SE NECESITA TIRAS SEMANALES | B10: =1270*20 -> 25400 | D10: =960*40 -> 38400
B11: =+B10-B8 -> -7240 | D11: =+D10-D8 -> 1920 | E11: =SUM(B11:D11) -> -5320

Sheet Hoja1
A1: Item ID | B1: Item Description | C1: ene | D1: feb | E1: mar | I1: Item ID | J1: Item Description
A2: PT10002 | B2: PIPAS E SAL - PACAS 400 U T-20 | C2: 559.5 | D2: 511 | E2: 553.5 | F2: =+VLOOKUP(A2,$I$2:$I$35,1,FALSE) -> PT10002 | I2: PT10001 | J2: PIPAS E SAL - PACAS 400 U T-10 | K2: =+VLOOKUP(I2,$A$2:$A$36,1,FALSE) -> PT10001
A3: PT20002 | B3: PIPAS MGA VER-PACAS 400 T-20 | C3: 2758.5 | D3: 2813.5 | E3: 3044.5 | F3: =+VLOOKUP(A3,$I$2:$I$35,1,FALSE) -> PT20002 | I3: PT10002 | J3: PIPAS E SAL - PACAS 400 U T-20 | K3: =+VLOOKUP(I3,$A$2:$A$36,1,FALSE) -> PT10002
A4: PT20003 | B4: PIPAS MGA VER 36 U GRN 120 G | C4: 733 | D4: 586 | E4: 724 | F4: =+VLOOKUP(A4,$I$2:$I$35,1,FALSE) -> PT20003 | I4: PT11001 | J4: PIPAS E PIC - PACAS 400 U T-10 | K4: =+VLOOKUP(I4,$A$2:$A$36,1,FALSE) -> PT11001
A5: PT23002 | B5: PIPAS MGA PIC-LIM-PAC 400 T-20 | C5: 536.5 | D5: 476 | E5: 593 | F5: =+VLOOKUP(A5,$I$2:$I$35,1,FALSE) -> PT23002 | I5: PT11002 | J5: PIPAS E PIC - PACAS 400 U T-20 | K5: =+VLOOKUP(I5,$A$2:$A$36,1,FALSE) -> PT11002
A6: PT22002 | B6: PIPAS MGA MRAC-LIM-PAC 400 T20 | C6: 640.5 | D6: 594 | E6: 707 | F6: =+VLOOKUP(A6,$I$2:$I$35,1,FALSE) -> PT22002 | I6: PT12001 | J6: PIPAS E LIM - PACAS 400 U T-10 | K6: =+VLOOKUP(I6,$A$2:$A$36,1,FALSE) -> PT12001
A7: PT21002 | B7: PIPAS MGA ACID-LEM-PAC 400 T20 | C7: 2114.5 | D7: 2003.5 | E7: 2435.5 | F7: =+VLOOKUP(A7,$I$2:$I$35,1,FALSE) -> PT21002 | I7: PT12002 | J7: PIPAS E LIM - PACAS 400 U T-20 | K7: =+VLOOKUP(I7,$A$2:$A$36,1,FALSE) -> PT12002
A8: PT12002 | B8: PIPAS E LIM - PACAS 400 U T-20 | C8: 77 | D8: 66 | E8: 66 | F8: =+VLOOKUP(A8,$I$2:$I$35,1,FALSE) -> PT12002 | I8: PT13001 | J8: PIPAS E MAR - PACAS 400 U T-10 | K8: =+VLOOKUP(I8,$A$2:$A$36,1,FALSE) -> PT13001
A9: PT72001 | B9: POLVO MGA MIX LIM-MARC 60 SOL | C9: 508.5 | D9: 661 | E9: 728.5 | F9: =+VLOOKUP(A9,$I$2:$I$35,1,FALSE) -> #N/A | I9: PT13002 | J9: PIPAS E MAR - PACAS 400 U T-20 | K9: =+VLOOKUP(I9,$A$2:$A$36,1,FALSE) -> #N/A
A10: PT70001 | B10: POLVO MGA LIMON PAC 60 SOL | C10: 124 | D10: 118 | E10: 144 | F10: =+VLOOKUP(A10,$I$2:$I$35,1,FALSE) -> #N/A | I10: PT20001 | J10: PIPAS MGA VER-PACAS 400 T-10 | K10: =+VLOOKUP(I10,$A$2:$A$36,1,FALSE) -> PT20001
A11: PT10003 | B11: PIPAS E SAL 36 U GRN 120G | C11: 572 | D11: 426 | E11: 533 | F11: =+VLOOKUP(A11,$I$2:$I$35,1,FALSE) -> PT10003 | I11: PT20002 | J11: PIPAS MGA VER-PACAS 400 T-20 | K11: =+VLOOKUP(I11,$A$2:$A$36,1,FALSE) -> PT20002
A12: PT71001 | B12: POLVO MGA MARACUYA PAC 60 SOL | C12: 52 | D12: 70 | E12: 70 | F12: =+VLOOKUP(A12,$I$2:$I$35,1,FALSE) -> #N/A | I12: PT20013 | J12: PIPAS MGA VERDE P 400 T20+2 | K12: =+VLOOKUP(I12,$A$2:$A$36,1,FALSE) -> PT20013
A13: PT21003 | B13: PIPAS MGA ACID-LEM 36 U GR 120 | C13: 438 | D13: 322 | E13: 505 | F13: =+VLOOKUP(A13,$I$2:$I$35,1,FALSE) -> PT21003 | I13: PT21001 | J13: PIPAS MGA ACID-LEM-PAC 400 T10 | K13: =+VLOOKUP(I13,$A$2:$A$36,1,FALSE) -> PT21001
... A21: PT22001 | B21: PIPAS MGA MRAC-LIM-PAC 400 T10 | C21: 840 | D21: 740 | E21: 793 | F21: =+VLOOKUP(A21,$I$2:$I$35,1,FALSE) -> PT22001 | I21: PT23002 | J21: PIPAS MGA PIC-LIM-PAC 400 T-20 | K21: =+VLOOKUP(I21,$A$2:$A$36,1,FALSE) -> PT23002
A22: PT12003 | B22: PIPAS E LIM 36 U GRN 120G | C22: 40 | D22: 30 | E22: 24 | F22: =+VLOOKUP(A22,$I$2:$I$35,1,FALSE) -> PT12003
A23: PT11001 | B23: PIPAS E PIC - PACAS 400 U T-10 | C23: 35 | D23: 34 | E23: 33 | F23: =+VLOOKUP(A23,$I$2:$I$35,1,FALSE) -> PT11001 | I23: PT10003 | J23: PIPAS E SAL 36 U GRN 120G | K23: =+VLOOKUP(I23,$A$2:$A$36,1,FALSE) -> PT10003
A24: PT11003 | B24: PIPAS E PIC 36 U GRN 120G | C24: 137 | D24: 82 | E24: 147 | F24: =+VLOOKUP(A24,$I$2:$I$35,1,FALSE) -> PT11003 | I24: PT10004 | J24: C PIPAS E SAL 36 U GRN 120G | K24: =+VLOOKUP(I24,$A$2:$A$36,1,FALSE) -> PT10004
A25: PT20006 | B25: PIPAS MGA VER PACA 400 U GRN | C25: 14 | D25: 5 | E25: 6 | F25: =+VLOOKUP(A25,$I$2:$I$35,1,FALSE) -> PT20006 | I25: PT11003 | J25: PIPAS E PIC 36 U GRN 120G | K25: =+VLOOKUP(I25,$A$2:$A$36,1,FALSE) -> PT11003
A26: PT21004 | B26: C PIPAS MGA AC-LEM 36 U 120 GR | C26: 203 | D26: 174 | E26: 224 | F26: =+VLOOKUP(A26,$I$2:$I$35,1,FALSE) -> PT21004 | I26: PT11004 | J26: C PIPAS E PIC 36 U GRN 120G | K26: =+VLOOKUP(I26,$A$2:$A$36,1,FALSE) -> PT11004
A27: PT20004 | B27: C PIPAS MGA VER 36 U GRN 120G | C27: 552 | D27: 738 | E27: 1042 | F27: =+VLOOKUP(A27,$I$2:$I$35,1,FALSE) -> PT20004 | I27: PT12003 | J27: PIPAS E LIM 36 U GRN 120G | K27: =+VLOOKUP(I27,$A$2:$A$36,1,FALSE) -> PT12003
A28: PT22004 | B28: C PIPAS MGA MRAC-LIM 36 U 120G | C28: 131 | D28: 117 | E28: 133 | F28: =+VLOOKUP(A28,$I$2:$I$35,1,FALSE) -> PT22004 | I28: PT12004 | J28: C PIPAS E LIM 36 U GRN 120G | K28: =+VLOOKUP(I28,$A$2:$A$36,1,FALSE) -> #N/A
A29: PT10004 | B29: C PIPAS E SAL 36 U GRN 120G | C29: 818 | D29: 1001 | E29: 1234 | F29: =+VLOOKUP(A29,$I$2:$I$35,1,FALSE) -> PT10004 | I29: PT20003 | J29: PIPAS MGA VER 36 U GRN 120 G | K29: =+VLOOKUP(I29,$A$2:$A$36,1,FALSE) -> PT20003
A30: PT70002 | B30: POLVO MGA LIMON GRN | C30: 44 | D30: 40 | E30: 40 | F30: =+VLOOKUP(A30,$I$2:$I$35,1,FALSE) -> #N/A | I30: PT20004 | J30: C PIPAS MGA VER 36 U GRN 120G | K30: =+VLOOKUP(I30,$A$2:$A$36,1,FALSE) -> PT20004
A31: PT71002 | B31: POLVO MGA MARACUYA GRN | C31: 38 | D31: 55 | E31: 48 | F31: =+VLOOKUP(A31,$I$2:$I$35,1,FALSE) -> #N/A | I31: PT21003 | J31: PIPAS MGA ACID-LEM 36 U GR 120 | K31: =+VLOOKUP(I31,$A$2:$A$36,1,FALSE) -> PT21003
A32: PT11002 | B32: PIPAS E PIC - PACAS 400 U T-20 | C32: 9 | D32: 12 | E32: 4 | F32: =+VLOOKUP(A32,$I$2:$I$35,1,FALSE) -> PT11002 | I32: PT21004 | J32: C PIPAS MGA AC-LEM 36 U 120 GR | K32: =+VLOOKUP(I32,$A$2:$A$36,1,FALSE) -> PT21004
A33: PT20013 | B33: PIPAS MGA VERDE P 400 T20+2 | C33: 227 | D33: 185 | E33: 234 | F33: =+VLOOKUP(A33,$I$2:$I$35,1,FALSE) -> PT20013 | I33: PT30001 | J33: C PIPAS SPINNY SAL CAJA 24U120 | K33: =+VLOOKUP(I33,$A$2:$A$36,1,FALSE) -> PT30001
A34: PT21006 | B34: PIPAS MGA ACID-LEM P 400 T20+2 | C34: 233 | D34: 242 | E34: 241 | F34: =+VLOOKUP(A34,$I$2:$I$35,1,FALSE) -> PT21006 | I34: PT22003 | J34: PIPAS MGA MRAC-LIM 36 U 120 G | K34: =+VLOOKUP(I34,$A$2:$A$36,1,FALSE) -> PT22003
A35: PT30001 | B35: C PIPAS SPINNY SAL CAJA 24U120 | C35: 209 | D35: 136 | E35: 185 | F35: =+VLOOKUP(A35,$I$2:$I$35,1,FALSE) -> PT30001 | I35: PT22004 | J35: C PIPAS MGA MRAC-LIM 36 U 120G | K35: =+VLOOKUP(I35,$A$2:$A$36,1,FALSE) -> PT22004
A36: PT11004 | B36: C PIPAS E PIC 36 U GRN 120G | C36: 60 | D36: 35 | E36: 45 | F36: =+VLOOKUP(A36,$I$2:$I$35,1,FALSE) -> PT11004
