Workbook

Sheet horno
B1: HORNO PEQ
A2: 8H | B2: =400*8 -> 3200
A3: 10.5H | B3: =450*10.5 -> 4725
B5: HORNO GRAN
A6: 8H | B6: =420*8 -> 3360
A7: 10.5H | B7: =550*10.5 -> 5775
B13: =+B2 -> 3200
B15: =+B2+B6 -> 6560

Sheet ANALISIS PROD
A1: Ventas 2023 | R1: CALCULO | S1: DESPACHOS | T1: CALCULO | U1: CALCULO | V1: CALCULO | X1: CALCULO | Y1: CONDICIONALES | Z1: CALCULO | AA1: CALCULO | AB1: CONDICIONALES | AC1: CALCULO | AE1: CALCULO
A2: Item ID | B2: Item Description | C2: ene | D2: feb | E2: mar | F2: abr | G2: may | H2: jun | I2: jul | J2: ago | K2: sep | L2: oct | M2: nov | N2: dic | O2: TOTAL PACAS | Q2: PACAS PROMEDIO MENSUAL | R2: (+) % INCREMENTO | S2: STOCK ACTUAL BODEGA | T2: STOK SEMANAL PACAS PROMEDIO | U2: DIF PACAS | V2: DIF UNIDADES | X2: PACAS PRODUCCION DIARIA | Y2: UNIDAD MANEJO | Z2: UNIDADES MENSUALES | AA2: UNIDADES DIARIAS | AB2: KG | AC2: KILOS DIARIOS | AE2: KILOS A CUMPLIR
A3: PT10001 | B3: PIPAS E SAL - PACAS 400 U T-10 | C3: 1016.5 | D3: 658.5 | E3: 756 | F3: 679.5 | G3: 895.5 | H3: 789 | I3: 735 | J3: 905 | K3: 745 | L3: 100.5 | O3: =SUM(C3:N3) -> 7280.5 | Q3: =+AVERAGE(C3:K3) -> 797.77778 | R3: =Q3*$R$47+Q3 -> 885.53333 | S3: =+VLOOKUP(A3,'INVENTARIO ACTUAL'!$A$2:$E$42,5,FALSE) -> 412.5 | T3: =+R3/4 -> 221.38333 | U3: =+S3-T3 -> 191.11667 | V3: =+U3*Y3 -> 76446.667 | X3: =+R3/20 -> 44.276667 | Y3: 400 | Z3: =+R3*Y3 -> 354213.33 | AA3: =+Z3/20 -> 17710.667 | AB3: 0.019 | AC3: =+AA3*AB3 -> 336.50267 | AE3: =+IF(V3<=0,V3*AB3,0) -> 0
A4: PT10002 | B4: PIPAS E SAL - PACAS 400 U T-20 | C4: 699.5 | D4: 522 | E4: 643 | F4: 588 | G4: 591 | H4: 536 | I4: 563 | J4: 617 | K4: 565 | L4: 88 | O4: =SUM(C4:N4) -> 5412.5 | Q4: =+AVERAGE(C4:K4) -> 591.61111 | R4: =+Q4*$R$47+Q4 -> 656.68833 | S4: =+VLOOKUP(A4,'INVENTARIO ACTUAL'!$A$2:$E$42,5,FALSE) -> 280 | T4: =+R4/4 -> 164.17208 | U4: =+S4-T4 -> 115.82792 | V4: =+U4*Y4 -> 46331.167 | X4: =+R4/20 -> 32.834417 | Y4: 400 | Z4: =+R4*Y4 -> 262675.33 | AA4: =+Z4/20 -> 13133.767 | AB4: 0.019 | AC4: =+AA4*AB4 -> 249.54157 | AE4: =+IF(V4<=0,V4*AB4,0) -> 0
A5: PT20001PT20001 | B5: PIPAS E PIC - PACAS 400 U T-10 | C5: 63.5 | D5: 36 | E5: 79 | F5: 85 | G5: 93 | H5: 54 | I5: 62 | J5: 73 | K5: 53 | L5: 9 | O5: =SUM(C5:N5) -> 607.5 | Q5: =+AVERAGE(C5:K5) -> 66.5 | R5: =+Q5*$R$47+Q5 -> 73.815 | S5: =+VLOOKUP(A5,'INVENTARIO ACTUAL'!$A$2:$E$42,5,FALSE) -> #N/A | T5: =+R5/4 -> 18.45375 | U5: =+S5-T5 -> #N/A | V5: =+U5*Y5 -> #N/A | X5: =+R5/20 -> 3.69075 | Y5: 400 | Z5: =+R5*Y5 -> 29526 | AA5: =+Z5/20 -> 1476.3 | AB5: 0.019 | AC5: =+AA5*AB5 -> 28.0497 | AE5: =+IF(V5<=0,V5*AB5,0) -> #N/A
A6: PT11002 | B6: PIPAS E PIC - PACAS 400 U T-20 | C6: 17 | D6: 9 | E6: 15 | F6: 5 | G6: 8 | H6: 8 | I6: 15 | J6: 18 | K6: 8 | L6: 2 | O6: =SUM(C6:N6) -> 105 | Q6: =+AVERAGE(C6:K6) -> 11.444444 | R6: =+Q6*$R$47+Q6 -> 12.703333 | S6: =+VLOOKUP(A6,'INVENTARIO ACTUAL'!$A$2:$E$42,5,FALSE) -> 11 | T6: =+R6/4 -> 3.1758333 | U6: =+S6-T6 -> 7.8241667 | V6: =+U6*Y6 -> 3129.6667 | X6: =+R6/20 -> 0.63516667 | Y6: 400 | Z6: =+R6*Y6 -> 5081.3333 | AA6: =+Z6/20 -> 254.06667 | AB6: 0.019 | AC6: =+AA6*AB6 -> 4.8272667 | AE6: =+IF(V6<=0,V6*AB6,0) -> 0
A7: PT12001 | B7: PIPAS E LIM - PACAS 400 U T-10 | C7: 533 | D7: 481 | E7: 544 | F7: 418.5 | G7: 606 | H7: 496 | I7: 562.5 | J7: 559 | K7: 514 | L7: 68 | O7: =SUM(C7:N7) -> 4782 | Q7: =+AVERAGE(C7:K7) -> 523.77778 | R7: =+Q7*$R$47+Q7 -> 581.39333 | S7: =+VLOOKUP(A7,'INVENTARIO ACTUAL'!$A$2:$E$42,5,FALSE) -> 43 | T7: =+R7/4 -> 145.34833 | U7: =+S7-T7 -> -102.34833 | V7: =+U7*Y7 -> -40939.333 | X7: =+R7/20 -> 29.069667 | Y7: 400 | Z7: =+R7*Y7 -> 232557.33 | AA7: =+Z7/20 -> 11627.867 | AB7: 0.019 | AC7: =+AA7*AB7 -> 220.92947 | AE7: =+IF(V7<=0,V7*AB7,0) -> -777.84733
A8: PT12002 | B8: PIPAS E LIM - PACAS 400 U T-20 | C8: 150 | D8: 81 | E8: 76 | F8: 91 | G8: 102 | H8: 77 | I8: 121 | J8: 94 | K8: 99 | L8: 4 | O8: =SUM(C8:N8) -> 895 | Q8: =+AVERAGE(C8:K8) -> 99 | R8: =+Q8*$R$47+Q8 -> 109.89 | S8: =+VLOOKUP(A8,'INVENTARIO ACTUAL'!$A$2:$E$42,5,FALSE) -> 15 | T8: =+R8/4 -> 27.4725 | U8: =+S8-T8 -> -12.4725 | V8: =+U8*Y8 -> -4989 | X8: =+R8/20 -> 5.4945 | Y8: 400 | Z8: =+R8*Y8 -> 43956 | AA8: =+Z8/20 -> 2197.8 | AB8: 0.019 | AC8: =+AA8*AB8 -> 41.7582 | AE8: =+IF(V8<=0,V8*AB8,0) -> -94.791
A9: PT13001 | B9: PIPAS E MAR - PACAS 400 U T-10 | C9: 155 | D9: 128 | E9: 80 | F9: 133 | G9: 224 | H9: 141 | I9: 160 | J9: 157 | K9: 160 | L9: 17 | O9: =SUM(C9:N9) -> 1355 | Q9: =+AVERAGE(C9:K9) -> 148.66667 | R9: =+Q9*$R$47+Q9 -> 165.02 | S9: =+VLOOKUP(A9,'INVENTARIO ACTUAL'!$A$2:$E$42,5,FALSE) -> 55 | T9: =+R9/4 -> 41.255 | U9: =+S9-T9 -> 13.745 | V9: =+U9*Y9 -> 5498 | X9: =+R9/20 -> 8.251 | Y9: 400 | Z9: =+R9*Y9 -> 66008 | AA9: =+Z9/20 -> 3300.4 | AB9: 0.019 | AC9: =+AA9*AB9 -> 62.7076 | AE9: =+IF(V9<=0,V9*AB9,0) -> 0
A10: PT13002 | B10: PIPAS E MAR - PACAS 400 U T-20 | C10: 0 | D10: 0 | E10: 0 | F10: 0 | G10: 0 | H10: 0 | I10: 0 | J10: 0 | K10: 0 | O10: =SUM(C10:N10) -> 0 | Q10: =+AVERAGE(C10:K10) -> 0 | R10: =+Q10*$R$47+Q10 -> 0 | T10: =+R10/4 -> 0 | U10: =+S10-T10 -> 0 | V10: =+U10*Y10 -> 0 | X10: =+R10/20 -> 0 | Y10: 400 | Z10: =+R10*Y10 -> 0 | AA10: =+Z10/20 -> 0 | AC10: =+AA10*AB10 -> 0 | AE10: =+IF(V10<=0,V10*AB10,0) -> 0
A11: PT20001 | B11: PIPAS MGA VER-PACAS 400 T-10 | C11: 1493.5 | D11: 965 | E11: 944.5 | F11: 1022 | G11: 1321 | H11: 1067 | I11: 1015.5 | J11: 1277 | K11: 1254 | L11: 134 | O11: =SUM(C11:N11) -> 10493.5 | Q11: =+AVERAGE(C11:K11) -> 1151.0556 | R11: =+Q11*$R$47+Q11 -> 1277.6717 | S11: =+VLOOKUP(A11,'INVENTARIO ACTUAL'!$A$2:$E$42,5,FALSE) -> 234.5 | T11: =+R11/4 -> 319.41792 | U11: =+S11-T11 -> -84.917917 | V11: =+U11*Y11 -> -33967.167 | X11: =+R11/20 -> 63.883583 | Y11: 400 | Z11: =+R11*Y11 -> 511068.67 | AA11: =+Z11/20 -> 25553.433 | AB11: 0.019 | AC11: =+AA11*AB11 -> 485.51523 | AE11: =+IF(V11<=0,V11*AB11,0) -> -645.37617
A12: PT20002 | B12: PIPAS MGA VER-PACAS 400 T-20 | C12: 3672 | D12: 3007 | E12: 3486 | F12: 3042.5 | G12: 3182.5 | H12: 2785 | I12: 2958.5 | J12: 2587 | K12: 3053 | L12: 576.5 | O12: =SUM(C12:N12) -> 28350 | Q12: =+AVERAGE(C12:K12) -> 3085.9444 | R12: =+Q12*$R$47+Q12 -> 3425.3983 | S12: =+VLOOKUP(A12,'INVENTARIO ACTUAL'!$A$2:$E$42,5,FALSE) -> 1144 | T12: =+R12/4 -> 856.34958 | U12: =+S12-T12 -> 287.65042 | V12: =+U12*Y12 -> 115060.17 | X12: =+R12/20 -> 171.26992 | Y12: 400 | Z12: =+R12*Y12 -> 1370159.3 | AA12: =+Z12/20 -> 68507.967 | AB12: 0.019 | AC12: =+AA12*AB12 -> 1301.6514 | AE12: =+IF(V12<=0,V12*AB12,0) -> 0
A13: PT21001 | B13: PIPAS MGA ACID-LEM-PAC 400 T10 | C13: 1866 | D13: 1140.5 | E13: 1069 | F13: 1226.5 | G13: 1562.5 | H13: 1574 | I13: 1639 | J13: 1741.5 | K13: 2214 | L13: 298 | O13: =SUM(C13:N13) -> 14331 | Q13: =+AVERAGE(C13:K13) -> 1559.2222 | R13: =+Q13*$R$47+Q13 -> 1730.7367 | S13: =+VLOOKUP(A13,'INVENTARIO ACTUAL'!$A$2:$E$42,5,FALSE) -> 142 | T13: =+R13/4 -> 432.68417 | U13: =+S13-T13 -> -290.68417 | V13: =+U13*Y13 -> -116273.67 | X13: =+R13/20 -> 86.536833 | Y13: 400 | Z13: =+R13*Y13 -> 692294.67 | AA13: =+Z13/20 -> 34614.733 | AB13: 0.019 | AC13: =+AA13*AB13 -> 657.67993 | AE13: =+IF(V13<=0,V13*AB13,0) -> -2209.1997
A14: PT21002 | B14: PIPAS MGA ACID-LEM-PAC 400 T20 | C14: 2262 | D14: 1771.5 | E14: 2323 | F14: 2068 | G14: 2157.5 | H14: 1886.5 | I14: 1744.5 | J14: 1671 | K14: 2083 | L14: 262.5 | O14: =SUM(C14:N14) -> 18229.5 | Q14: =+AVERAGE(C14:K14) -> 1996.3333 | R14: =+Q14*$R$47+Q14 -> 2215.93 | S14: =+VLOOKUP(A14,'INVENTARIO ACTUAL'!$A$2:$E$42,5,FALSE) -> 173 | T14: =+R14/4 -> 553.9825 | U14: =+S14-T14 -> -380.9825 | V14: =+U14*Y14 -> -152393 | X14: =+R14/20 -> 110.7965 | Y14: 400 | Z14: =+R14*Y14 -> 886372 | AA14: =+Z14/20 -> 44318.6 | AB14: 0.019 | AC14: =+AA14*AB14 -> 842.0534 | AE14: =+IF(V14<=0,V14*AB14,0) -> -2895.467
A15: PT21006 | B15: PIPAS MGA ACID-LEM P 400 T20+2 | C15: 0 | D15: 0 | E15: 0 | F15: 0 | G15: 0 | H15: 0 | I15: 0 | J15: 0 | K15: 0 | L15: 157 | O15: =SUM(C15:N15) -> 157 | Q15: =+AVERAGE(K15) -> 0 | R15: =+Q15*$R$47+Q15 -> 0 | S15: =+VLOOKUP(A15,'INVENTARIO ACTUAL'!$A$2:$E$42,5,FALSE) -> 151 | T15: =+R15/4 -> 0 | U15: =+S15-T15 -> 151 | V15: =+U15*Y15 -> 66440 | X15: =+R15/20 -> 0 | Y15: 440 | Z15: =+R15*Y15 -> 0 | AA15: =+Z15/20 -> 0 | AC15: =+AA15*AB15 -> 0 | AE15: =+IF(V15<=0,V15*AB15,0) -> 0
A16: PT20006 | B16: PIPAS MGA VER PACA 400 U GRN | C16: 13 | D16: 9 | E16: 9 | F16: 6 | G16: 6 | H16: 8 | I16: 19 | J16: 19 | K16: 16 | L16: 0 | O16: =SUM(C16:N16) -> 105 | Q16: =+AVERAGE(C16:K16) -> 11.666667 | R16: =+Q16*$R$47+Q16 -> 12.95 | S16: =+VLOOKUP(A16,'INVENTARIO ACTUAL'!$A$2:$E$42,5,FALSE) -> 16 | T16: =+R16/4 -> 3.2375 | U16: =+S16-T16 -> 12.7625 | V16: =+U16*Y16 -> 5105 | X16: =+R16/20 -> 0.6475 | Y16: 400 | Z16: =+R16*Y16 -> 5180 | AA16: =+Z16/20 -> 259 | AB16: 0.019 | AC16: =+AA16*AB16 -> 4.921 | AE16: =+IF(V16<=0,V16*AB16,0) -> 0
A17: PT21005 | B17: PIPAS MGA ACID-LEM PACA 400 GR | C17: 12 | D17: 5 | E17: 9 | F17: 4 | G17: 7 | H17: 6 | I17: 4 | J17: 9 | K17: 3 | L17: 0 | O17: =SUM(C17:N17) -> 59 | Q17: =+AVERAGE(C17:K17) -> 6.5555556 | R17: =+Q17*$R$47+Q17 -> 7.2766667 | S17: =+VLOOKUP(A17,'INVENTARIO ACTUAL'!$A$2:$E$42,5,FALSE) -> 4 | T17: =+R17/4 -> 1.8191667 | U17: =+S17-T17 -> 2.1808333 | V17: =+U17*Y17 -> 872.33333 | X17: =+R17/20 -> 0.36383333 | Y17: 400 | Z17: =+R17*Y17 -> 2910.6667 | AA17: =+Z17/20 -> 145.53333 | AB17: 0.019 | AC17: =+AA17*AB17 -> 2.7651333 | AE17: =+IF(V17<=0,V17*AB17,0) -> 0
A18: PT22001 | B18: PIPAS MGA MRAC-LIM-PAC 400 T10 | C18: 1289.5 | D18: 795 | E18: 909.5 | F18: 721 | G18: 1150 | H18: 1025.5 | I18: 1102 | J18: 1077.5 | K18: 1123.5 | L18: 176 | O18: =SUM(C18:N18) -> 9369.5 | Q18: =+AVERAGE(C18:K18) -> 1021.5 | R18: =+Q18*$R$47+Q18 -> 1133.865 | S18: =+VLOOKUP(A18,'INVENTARIO ACTUAL'!$A$2:$E$42,5,FALSE) -> 370.5 | T18: =+R18/4 -> 283.46625 | U18: =+S18-T18 -> 87.03375 | V18: =+U18*Y18 -> 34813.5 | X18: =+R18/20 -> 56.69325 | Y18: 400 | Z18: =+R18*Y18 -> 453546 | AA18: =+Z18/20 -> 22677.3 | AB18: 0.019 | AC18: =+AA18*AB18 -> 430.8687 | AE18: =+IF(V18<=0,V18*AB18,0) -> 0
A19: PT22002 | B19: PIPAS MGA MRAC-LIM-PAC 400 T20 | C19: 930 | D19: 697 | E19: 683 | F19: 677 | G19: 732.5 | H19: 649.5 | I19: 642.5 | J19: 646 | K19: 645.5 | L19: 125 | O19: =SUM(C19:N19) -> 6428 | Q19: =+AVERAGE(C19:K19) -> 700.33333 | R19: =+Q19*$R$47+Q19 -> 777.37 | S19: =+VLOOKUP(A19,'INVENTARIO ACTUAL'!$A$2:$E$42,5,FALSE) -> 370 | T19: =+R19/4 -> 194.3425 | U19: =+S19-T19 -> 175.6575 | V19: =+U19*Y19 -> 70263 | X19: =+R19/20 -> 38.8685 | Y19: 400 | Z19: =+R19*Y19 -> 310948 | AA19: =+Z19/20 -> 15547.4 | AB19: 0.019 | AC19: =+AA19*AB19 -> 295.4006 | AE19: =+IF(V19<=0,V19*AB19,0) -> 0
A20: PT23001 | B20: PIPAS MGA PIC-LIM-PAC 400 T-10 | C20: 547 | D20: 425.5 | E20: 363 | F20: 390 | G20: 587.5 | H20: 537.5 | I20: 644.5 | J20: 734.5 | K20: 618 | L20: 80 | O20: =SUM(C20:N20) -> 4927.5 | Q20: =+AVERAGE(C20:K20) -> 538.61111 | R20: =+Q20*$R$47+Q20 -> 597.85833 | S20: =+VLOOKUP(A20,'INVENTARIO ACTUAL'!$A$2:$E$42,5,FALSE) -> 205.5 | T20: =+R20/4 -> 149.46458 | U20: =+S20-T20 -> 56.035417 | V20: =+U20*Y20 -> 22414.167 | X20: =+R20/20 -> 29.892917 | Y20: 400 | Z20: =+R20*Y20 -> 239143.33 | AA20: =+Z20/20 -> 11957.167 | AB20: 0.019 | AC20: =+AA20*AB20 -> 227.18617 | AE20: =+IF(V20<=0,V20*AB20,0) -> 0
A21: PT23002 | B21: PIPAS MGA PIC-LIM-PAC 400 T-20 | C21: 541.5 | D21: 469 | E21: 518 | F21: 521.5 | G21: 541 | H21: 533 | I21: 435.5 | J21: 442 | K21: 466.5 | L21: 89 | O21: =SUM(C21:N21) -> 4557 | Q21: =+AVERAGE(C21:K21) -> 496.44444 | R21: =+Q21*$R$47+Q21 -> 551.05333 | S21: =+VLOOKUP(A21,'INVENTARIO ACTUAL'!$A$2:$E$42,5,FALSE) -> 182 | T21: =+R21/4 -> 137.76333 | U21: =+S21-T21 -> 44.236667 | V21: =+U21*Y21 -> 17694.667 | X21: =+R21/20 -> 27.552667 | Y21: 400 | Z21: =+R21*Y21 -> 220421.33 | AA21: =+Z21/20 -> 11021.067 | AB21: 0.019 | AC21: =+AA21*AB21 -> 209.40027 | AE21: =+IF(V21<=0,V21*AB21,0) -> 0
O22: =SUM(C22:N22) -> 0 | T22: =+R22/4 -> 0 | U22: =+S22-T22 -> 0 | V22: =+U22*Y22 -> 0 | AA22: =+Z22/20 -> 0 | AC22: =+AA22*AB22 -> 0 | AE22: =+IF(V22<=0,V22*AB22,0) -> 0
A23: PT10003 | B23: PIPAS E SAL 36 U GRN 120G | C23: 475 | D23: 403 | E23: 516 | F23: 489 | G23: 418 | H23: 434 | I23: 493 | J23: 547 | K23: 502 | L23: 105 | O23: =SUM(C23:N23) -> 4382 | Q23: =+AVERAGE(C23:K23) -> 475.22222 | R23: =+Q23*$R$47+Q23 -> 527.49667 | S23: =+VLOOKUP(A23,'INVENTARIO ACTUAL'!$A$2:$E$42,5,FALSE) -> 54 | T23: =+R23/4 -> 131.87417 | U23: =+S23-T23 -> -77.874167 | V23: =+U23*Y23 -> -2803.47 | X23: =+R23/20 -> 26.374833 | Y23: 36 | Z23: =+R23*Y23 -> 18989.88 | AA23: =+Z23/20 -> 949.494 | AB23: 0.12 | AC23: =+AA23*AB23 -> 113.93928 | AE23: =+IF(V23<=0,V23*AB23,0) -> -336.4164
A24: PT10004 | B24: C PIPAS E SAL 36 U GRN 120G | C24: 877 | D24: 666 | E24: 808 | F24: 799 | G24: 996 | H24: 743 | I24: 964 | J24: 754 | K24: 860 | L24: 291 | O24: =SUM(C24:N24) -> 7758 | Q24: =+AVERAGE(C24:K24) -> 829.66667 | R24: =+Q24*$R$47+Q24 -> 920.93 | S24: =+VLOOKUP(A24,'INVENTARIO ACTUAL'!$A$2:$E$42,5,FALSE) -> 12 | T24: =+R24/4 -> 230.2325 | U24: =+S24-T24 -> -218.2325 | V24: =+U24*Y24 -> -7856.37 | X24: =+R24/20 -> 46.0465 | Y24: 36 | Z24: =+R24*Y24 -> 33153.48 | AA24: =+Z24/20 -> 1657.674 | AB24: 0.12 | AC24: =+AA24*AB24 -> 198.92088 | AE24: =+IF(V24<=0,V24*AB24,0) -> -942.7644
A25: PT11003 | B25: PIPAS E PIC 36 U GRN 120G | C25: 74 | D25: 83 | E25: 96 | F25: 93 | G25: 71 | H25: 90 | I25: 101 | J25: 94 | K25: 108 | L25: 10 | O25: =SUM(C25:N25) -> 820 | Q25: =+AVERAGE(C25:K25) -> 90 | R25: =+Q25*$R$47+Q25 -> 99.9 | S25: =+VLOOKUP(A25,'INVENTARIO ACTUAL'!$A$2:$E$42,5,FALSE) -> 37 | T25: =+R25/4 -> 24.975 | U25: =+S25-T25 -> 12.025 | V25: =+U25*Y25 -> 432.9 | X25: =+R25/20 -> 4.995 | Y25: 36 | Z25: =+R25*Y25 -> 3596.4 | AA25: =+Z25/20 -> 179.82 | AB25: 0.12 | AC25: =+AA25*AB25 -> 21.5784 | AE25: =+IF(V25<=0,V25*AB25,0) -> 0
A26: PT11004 | B26: C PIPAS E PIC 36 U GRN 120G | C26: 41 | D26: 61 | E26: 91 | F26: 57 | G26: 13 | H26: 225 | I26: 12 | J26: 17 | K26: 11 | L26: 4 | O26: =SUM(C26:N26) -> 532 | Q26: =+AVERAGE(C26:K26) -> 58.666667 | R26: =+Q26*$R$47+Q26 -> 65.12 | S26: =+VLOOKUP(A26,'INVENTARIO ACTUAL'!$A$2:$E$42,5,FALSE) -> 18 | T26: =+R26/4 -> 16.28 | U26: =+S26-T26 -> 1.72 | V26: =+U26*Y26 -> 61.92 | X26: =+R26/20 -> 3.256 | Y26: 36 | Z26: =+R26*Y26 -> 2344.32 | AA26: =+Z26/20 -> 117.216 | AB26: 0.12 | AC26: =+AA26*AB26 -> 14.06592 | AE26: =+IF(V26<=0,V26*AB26,0) -> 0
A27: PT12003 | B27: PIPAS E LIM 36 U GRN 120G | C27: 54 | D27: 29 | E27: 43 | F27: 37 | G27: 56 | H27: 24 | I27: 39 | J27: 41 | K27: 55 | L27: 2 | O27: =SUM(C27:N27) -> 380 | Q27: =+AVERAGE(C27:K27) -> 42 | R27: =+Q27*$R$47+Q27 -> 46.62 | S27: =+VLOOKUP(A27,'INVENTARIO ACTUAL'!$A$2:$E$42,5,FALSE) -> 51 | T27: =+R27/4 -> 11.655 | U27: =+S27-T27 -> 39.345 | V27: =+U27*Y27 -> 1416.42 | X27: =+R27/20 -> 2.331 | Y27: 36 | Z27: =+R27*Y27 -> 1678.32 | AA27: =+Z27/20 -> 83.916 | AB27: 0.12 | AC27: =+AA27*AB27 -> 10.06992 | AE27: =+IF(V27<=0,V27*AB27,0) -> 0
A28: PT12004 | B28: C PIPAS E LIM 36 U GRN 120G | C28: 46 | D28: 49 | E28: 51 | F28: 45 | G28: 39 | H28: 43 | I28: 46 | J28: 52 | K28: 32 | L28: 11 | O28: =SUM(C28:N28) -> 414 | Q28: =+AVERAGE(C28:K28) -> 44.777778 | R28: =+Q28*$R$47+Q28 -> 49.703333 | S28: =+VLOOKUP(A28,'INVENTARIO ACTUAL'!$A$2:$E$42,5,FALSE) -> 40 | T28: =+R28/4 -> 12.425833 | U28: =+S28-T28 -> 27.574167 | V28: =+U28*Y28 -> 992.67 | X28: =+R28/20 -> 2.4851667 | Y28: 36 | Z28: =+R28*Y28 -> 1789.32 | AA28: =+Z28/20 -> 89.466 | AB28: 0.12 | AC28: =+AA28*AB28 -> 10.73592 | AE28: =+IF(V28<=0,V28*AB28,0) -> 0
A29: PT20003 | B29: PIPAS MGA VER 36 U GRN 120 G | C29: 710 | D29: 593 | E29: 684 | F29: 675 | G29: 591 | H29: 583 | I29: 663 | J29: 732 | K29: 641 | L29: 119 | O29: =SUM(C29:N29) -> 5991 | Q29: =+AVERAGE(C29:K29) -> 652.44444 | R29: =+Q29*$R$47+Q29 -> 724.21333 | S29: =+VLOOKUP(A29,'INVENTARIO ACTUAL'!$A$2:$E$42,5,FALSE) -> 10 | T29: =+R29/4 -> 181.05333 | U29: =+S29-T29 -> -171.05333 | V29: =+U29*Y29 -> -6157.92 | X29: =+R29/20 -> 36.210667 | Y29: 36 | Z29: =+R29*Y29 -> 26071.68 | AA29: =+Z29/20 -> 1303.584 | AB29: 0.12 | AC29: =+AA29*AB29 -> 156.43008 | AE29: =+IF(V29<=0,V29*AB29,0) -> -738.9504
A30: PT20004 | B30: C PIPAS MGA VER 36 U GRN 120G | C30: 1079 | D30: 362 | E30: 483 | F30: 586 | G30: 916 | H30: 404 | I30: 708 | J30: 605 | K30: 582 | L30: 209 | O30: =SUM(C30:N30) -> 5934 | Q30: =+AVERAGE(C30:K30) -> 636.11111 | R30: =+Q30*$R$47+Q30 -> 706.08333 | S30: =+VLOOKUP(A30,'INVENTARIO ACTUAL'!$A$2:$E$42,5,FALSE) -> 12 | T30: =+R30/4 -> 176.52083 | U30: =+S30-T30 -> -164.52083 | V30: =+U30*Y30 -> -5922.75 | X30: =+R30/20 -> 35.304167 | Y30: 36 | Z30: =+R30*Y30 -> 25419 | AA30: =+Z30/20 -> 1270.95 | AB30: 0.12 | AC30: =+AA30*AB30 -> 152.514 | AE30: =+IF(V30<=0,V30*AB30,0) -> -710.73
A31: PT21003 | B31: PIPAS MGA ACID-LEM 36 U GR 120 | C31: 361 | D31: 266 | E31: 336 | F31: 314 | G31: 308 | H31: 350 | I31: 302 | J31: 359 | K31: 338 | L31: 69 | O31: =SUM(C31:N31) -> 3003 | Q31: =+AVERAGE(C31:K31) -> 326 | R31: =+Q31*$R$47+Q31 -> 361.86 | S31: =+VLOOKUP(A31,'INVENTARIO ACTUAL'!$A$2:$E$42,5,FALSE) -> 54 | T31: =+R31/4 -> 90.465 | U31: =+S31-T31 -> -36.465 | V31: =+U31*Y31 -> -1312.74 | X31: =+R31/20 -> 18.093 | Y31: 36 | Z31: =+R31*Y31 -> 13026.96 | AA31: =+Z31/20 -> 651.348 | AB31: 0.12 | AC31: =+AA31*AB31 -> 78.16176 | AE31: =+IF(V31<=0,V31*AB31,0) -> -157.5288
A32: PT21004 | B32: C PIPAS MGA AC-LEM 36 U 120 GR | C32: 135 | D32: 79 | E32: 166 | F32: 183 | G32: 296 | H32: 151 | I32: 352 | J32: 180 | K32: 103 | L32: 49 | O32: =SUM(C32:N32) -> 1694 | Q32: =+AVERAGE(C32:K32) -> 182.77778 | R32: =+Q32*$R$47+Q32 -> 202.88333 | S32: =+VLOOKUP(A32,'INVENTARIO ACTUAL'!$A$2:$E$42,5,FALSE) -> 57 | T32: =+R32/4 -> 50.720833 | U32: =+S32-T32 -> 6.2791667 | V32: =+U32*Y32 -> 226.05 | X32: =+R32/20 -> 10.144167 | Y32: 36 | Z32: =+R32*Y32 -> 7303.8 | AA32: =+Z32/20 -> 365.19 | AB32: 0.12 | AC32: =+AA32*AB32 -> 43.8228 | AE32: =+IF(V32<=0,V32*AB32,0) -> 0
A33: PT30001 | B33: C PIPAS SPINNY SAL CAJA 24U120 | C33: 187 | D33: 159 | E33: 258 | F33: 210 | G33: 298 | H33: 208 | I33: 204 | J33: 151 | K33: 153 | L33: 60 | O33: =SUM(C33:N33) -> 1888 | Q33: =+AVERAGE(C33:K33) -> 203.11111 | R33: =+Q33*$R$47+Q33 -> 225.45333 | S33: =+VLOOKUP(A33,'INVENTARIO ACTUAL'!$A$2:$E$42,5,FALSE) -> 45 | T33: =+R33/4 -> 56.363333 | U33: =+S33-T33 -> -11.363333 | V33: =+U33*Y33 -> -272.72 | X33: =+R33/20 -> 11.272667 | Y33: 24 | Z33: =+R33*Y33 -> 5410.88 | AA33: =+Z33/20 -> 270.544 | AB33: 0.12 | AC33: =+AA33*AB33 -> 32.46528 | AE33: =+IF(V33<=0,V33*AB33,0) -> -32.7264
A34: PT22003 | B34: PIPAS MGA MRAC-LIM 36 U 120 G | C34: 0 | D34: 0 | E34: 0 | F34: 0 | G34: 0 | H34: 249 | I34: 141 | J34: 145 | K34: 136 | L34: 35 | O34: =SUM(C34:N34) -> 706 | Q34: =+AVERAGE(H34:K34) -> 167.75 | R34: =+Q34*$R$47+Q34 -> 186.2025 | S34: =+VLOOKUP(A34,'INVENTARIO ACTUAL'!$A$2:$E$42,5,FALSE) -> 77 | T34: =+R34/4 -> 46.550625 | U34: =+S34-T34 -> 30.449375 | V34: =+U34*Y34 -> 1096.1775 | X34: =+R34/20 -> 9.310125 | Y34: 36 | Z34: =+R34*Y34 -> 6703.29 | AA34: =+Z34/20 -> 335.1645 | AB34: 0.12 | AC34: =+AA34*AB34 -> 40.21974 | AE34: =+IF(V34<=0,V34*AB34,0) -> 0
A35: PT22004 | B35: C PIPAS MGA MRAC-LIM 36 U 120G | C35: 0 | D35: 0 | E35: 0 | F35: 0 | G35: 0 | H35: 25 | I35: 133 | J35: 89 | K35: 139 | L35: 39 | O35: =SUM(C35:N35) -> 425 | Q35: =+AVERAGE(H35:K35) -> 96.5 | R35: =+Q35*$R$47+Q35 -> 107.115 | S35: =+VLOOKUP(A35,'INVENTARIO ACTUAL'!$A$2:$E$42,5,FALSE) -> 67 | T35: =+R35/4 -> 26.77875 | U35: =+S35-T35 -> 40.22125 | V35: =+U35*Y35 -> 1447.965 | X35: =+R35/20 -> 5.35575 | Y35: 36 | Z35: =+R35*Y35 -> 3856.14 | AA35: =+Z35/20 -> 192.807 | AB35: 0.12 | AC35: =+AA35*AB35 -> 23.13684 | AE35: =+IF(V35<=0,V35*AB35,0) -> 0
C36: =SUM(C3:C35) -> 19300 | D36: =SUM(D3:D35) -> 13950 | E36: =SUM(E3:E35) -> 16039 | F36: =SUM(F3:F35) -> 15166.5 | G36: =SUM(G3:G35) -> 17769 | H36: =SUM(H3:H35) -> 15702 | I36: =SUM(I3:I35) -> 16581.5 | J36: =SUM(J3:J35) -> 16393.5 | ... L36: =SUM(L3:L35) -> 3189.5 | O36: =SUM(O3:O35) -> 151371.5 | Q36: =SUM(Q3:Q35) -> 16611.472 | R36: =SUM(R3:R35) -> 18438.734 | S36: =SUM(S3:S35) -> #N/A | T36: =SUM(T3:T35) -> 4609.6835 | U36: =SUM(U3:U35) -> #N/A | V36: =SUM(V3:V35) -> #N/A | X36: =SUM(X3:X35) -> 921.93671 | Z36: =SUM(Z3:Z35) -> 5835404.8 | AA36: =SUM(AA3:AA35) -> 291770.24 | AC36: =SUM(AC3:AC35) -> 6297.8191 | AE36: =SUM(AE3:AE35) -> #N/A
A38: PT70001 | B38: POLVO MEGA LIMON PAC 60 SOL | C38: 133 | D38: 107 | E38: 162 | F38: 136 | G38: 124 | H38: 86 | I38: 73 | J38: 128 | K38: 161 | L38: 46 | O38: =SUM(C38:N38) -> 1156 | Q38: =+AVERAGE(C38:K38) -> 123.33333 | R38: =+Q38*$R$47+Q38 -> 136.9 | S38: =+VLOOKUP(A38,'INVENTARIO ACTUAL'!$A$2:$E$42,5,FALSE) -> 4 | T38: =+R38/4 -> 34.225 | U38: =+S38-T38 -> -30.225 | V38: =+U38*Y38 -> -72540 | X38: =+R38/20 -> 6.845 | Y38: 2400 | Z38: =+R38*Y38 -> 328560 | AA38: =+Z38/20 -> 16428 | AB38: 0.002 | AC38: =+AA38*AB38 -> 32.856 | AE38: =+IF(V38<=0,V38*AB38,0) -> -145.08
A39: PT70002 | B39: POLVO MEGA LIMON GRN | C39: 37 | D39: 23 | E39: 24 | F39: 20 | G39: 49 | H39: 55 | I39: 32 | J39: 28 | K39: 56 | L39: 10 | O39: =SUM(C39:N39) -> 334 | Q39: =+AVERAGE(C39:K39) -> 36 | R39: =+Q39*$R$47+Q39 -> 39.96 | S39: =+VLOOKUP(A39,'INVENTARIO ACTUAL'!$A$2:$E$42,5,FALSE) -> 26 | T39: =+R39/4 -> 9.99 | U39: =+S39-T39 -> 16.01 | V39: =+U39*Y39 -> 38424 | X39: =+R39/20 -> 1.998 | Y39: 2400 | Z39: =+R39*Y39 -> 95904 | AA39: =+Z39/20 -> 4795.2 | AB39: 0.002 | AC39: =+AA39*AB39 -> 9.5904 | AE39: =+IF(V39<=0,V39*AB39,0) -> 0
A40: PT71001 | B40: POLVO MEGA MARACYA PAC 60 SOL | C40: 97 | D40: 53 | E40: 91 | F40: 113 | G40: 77 | H40: 65 | I40: 72 | J40: 74 | K40: 79 | L40: 8 | O40: =SUM(C40:N40) -> 729 | Q40: =+AVERAGE(C40:K40) -> 80.111111 | R40: =+Q40*$R$47+Q40 -> 88.923333 | S40: =+VLOOKUP(A40,'INVENTARIO ACTUAL'!$A$2:$E$42,5,FALSE) -> 4 | T40: =+R40/4 -> 22.230833 | U40: =+S40-T40 -> -18.230833 | V40: =+U40*Y40 -> -43754 | X40: =+R40/20 -> 4.4461667 | Y40: 2400 | Z40: =+R40*Y40 -> 213416 | AA40: =+Z40/20 -> 10670.8 | AB40: 0.002 | AC40: =+AA40*AB40 -> 21.3416 | AE40: =+IF(V40<=0,V40*AB40,0) -> -87.508
A41: PT71002 | B41: POLVO MEGA MARACUYA GRN | C41: 13 | D41: 15 | E41: 15 | F41: 15 | G41: 27 | H41: 89 | I41: 77 | J41: 17 | K41: 76 | L41: 36 | O41: =SUM(C41:N41) -> 380 | Q41: =+AVERAGE(C41:K41) -> 38.222222 | R41: =+Q41*$R$47+Q41 -> 42.426667 | S41: =+VLOOKUP(A41,'INVENTARIO ACTUAL'!$A$2:$E$42,5,FALSE) -> 18 | T41: =+R41/4 -> 10.606667 | U41: =+S41-T41 -> 7.3933333 | V41: =+U41*Y41 -> 17744 | X41: =+R41/20 -> 2.1213333 | Y41: 2400 | Z41: =+R41*Y41 -> 101824 | AA41: =+Z41/20 -> 5091.2 | AB41: 0.002 | AC41: =+AA41*AB41 -> 10.1824 | AE41: =+IF(V41<=0,V41*AB41,0) -> 0
...

Sheet INVENTARIO ACTUAL
A1: ITEM | B1: DESCRIPCION | C1: INGRESOS | D1: DESPACHOS | E1: SALDO
A2: PT10001 | B2: PIPAS E SAL - PACAS 400 U T-10 | C2: 7888 | D2: 7475.5 | E2: =C2-D2 -> 412.5 | F2: =+VLOOKUP(A2,'ANALISIS PROD'!$A$3:$A$43,1,FALSE) -> PT10001
A3: PT10002 | B3: PIPAS E SAL - PACAS 400 U T-20 | C3: 5728 | D3: 5448 | E3: 280 | F3: =+VLOOKUP(A3,'ANALISIS PROD'!$A$3:$A$43,1,FALSE) -> PT10002
A4: PT10003 | B4: PIPAS E SAL 36 U GRN 120G | C4: 4648 | D4: 4594 | E4: 54 | F4: =+VLOOKUP(A4,'ANALISIS PROD'!$A$3:$A$43,1,FALSE) -> PT10003
A5: PT10004 | B5: C PIPAS E SAL 36 U GRN 120G | C5: 7815 | D5: 7803 | E5: 12 | F5: =+VLOOKUP(A5,'ANALISIS PROD'!$A$3:$A$43,1,FALSE) -> PT10004
A6: PT10009 | B6: PIPAS E SAL DEGUSTACION | C6: 315 | D6: 296 | E6: 19 | F6: =+VLOOKUP(A6,'ANALISIS PROD'!$A$3:$A$43,1,FALSE) -> #N/A
A7: PT11001 | B7: PIPAS E PIC - PACAS 400 U T-10 | C7: 617.5 | D7: 592.5 | E7: 25 | F7: =+VLOOKUP(A7,'ANALISIS PROD'!$A$3:$A$43,1,FALSE) -> #N/A
A8: PT11002 | B8: PIPAS E PIC - PACAS 400 U T-20 | C8: 116 | D8: 105 | E8: 11 | F8: =+VLOOKUP(A8,'ANALISIS PROD'!$A$3:$A$43,1,FALSE) -> PT11002
A9: PT11003 | B9: PIPAS E PIC 36 U GRN 120G | C9: 860 | D9: 823 | E9: 37 | F9: =+VLOOKUP(A9,'ANALISIS PROD'!$A$3:$A$43,1,FALSE) -> PT11003
A10: PT11004 | B10: C PIPAS E PIC 36 U GRN 120G | C10: 558 | D10: 540 | E10: 18 | F10: =+VLOOKUP(A10,'ANALISIS PROD'!$A$3:$A$43,1,FALSE) -> PT11004
A11: PT12001 | B11: PIPAS E LIM - PACAS 400 U T-10 | C11: 4929 | D11: 4886 | E11: 43 | F11: =+VLOOKUP(A11,'ANALISIS PROD'!$A$3:$A$43,1,FALSE) -> PT12001
A12: PT12002 | B12: PIPAS E LIM - PACAS 400 U T-20 | C12: 956 | D12: 941 | E12: 15 | F12: =+VLOOKUP(A12,'ANALISIS PROD'!$A$3:$A$43,1,FALSE) -> PT12002
A13: PT12003 | B13: PIPAS E LIM 36 U GRN 120G | C13: 436 | D13: 385 | E13: 51 | F13: =+VLOOKUP(A13,'ANALISIS PROD'!$A$3:$A$43,1,FALSE) -> PT12003
A14: PT12004 | B14: C PIPAS E LIM 36 U GRN 120G | C14: 454 | D14: 414 | E14: 40 | F14: =+VLOOKUP(A14,'ANALISIS PROD'!$A$3:$A$43,1,FALSE) -> PT12004
... A42: PT21006 | B42: PIPAS MGA ACID-LEM P 400 T20+2 | C42: 506 | D42: 354 | E42: 151 | F42: =+VLOOKUP(A42,'ANALISIS PROD'!$A$3:$A$43,1,FALSE) -> PT21006
